Workbook

Sheet Genel Kasa
A2: KASALAR | G2: ANLIK BİLANÇO TAKİBİ
B3: BORÇ | C3: ALACAK | D3: KASA BAKİYELERİ
A4: MAKSİ KASA | D4: =(Kasa!D16+Kasa!D17+Kasa!D18+Kasa!D19+Kasa!D20+Kasa!D21+Kasa!D22+Kasa!D23)+(Kasa!G3)-(Kasa!C3+Kasa!H3) -> 44953.69 | G4: SİTE ÜYELERİ YATIRIM | H4: =SUM('1'!I1,'2'!I1,'3'!I1,'4'!I1,'5'!I1,'6'!I1,'7'!I1,'8'!I1,'9'!I1,'10'!I1,'11'!I1,'12'!I1,'13'!I1,'14'!I1,'15'!I1,'16'!I1,'17'!I1,'18'!I1,'19'!I1,'20'!I1,'21'!I1,'22'!I1,'23'!I1,'24'!I1,'25'!I1,'26'!I1,'27'!I1,'28'!I1,'29'!I1,'30'!I1,'31'!I1) -> 23443.87
A5: PLUS KASA | D5: =(Kasa!D24+Kasa!D25)+(Kasa!G4)-(Kasa!C4+Kasa!H4) -> 5128.75 | G5: SİTE ÜYELERİ ÇEKİM | H5: =SUM('1'!I2,'2'!I2,'3'!I2,'4'!I2,'5'!I2,'6'!I2,'7'!I2,'8'!I2,'9'!I2,'10'!I2,'11'!I2,'12'!I2,'13'!I2,'14'!I2,'15'!I2,'16'!I2,'17'!I2,'18'!I2,'19'!I2,'20'!I2,'21'!I2,'22'!I2,'23'!I2,'24'!I2,'25'!I2,'26'!I2,'27'!I2,'28'!I2,'29'!I2,'30'!I2,'31'!I2) -> 12496
A6: FTN KASA | D6: =(Kasa!D26)+(Kasa!G5)-(Kasa!C5+Kasa!H5) -> 0 | G6: SİTE ÜYELERİ YATIRIM-ÇEKİM FARKI | H6: =SUM('1'!I5,'2'!I5,'3'!I5,'4'!I5,'5'!I5,'6'!I5,'7'!I5,'8'!I5,'9'!I5,'10'!I5,'11'!I5,'12'!I5,'13'!I5,'14'!I5,'15'!I5,'16'!I5,'17'!I5,'18'!I5,'19'!I5,'20'!I5,'21'!I5,'22'!I5,'23'!I5,'24'!I5,'25'!I5,'26'!I5,'27'!I5,'28'!I5,'29'!I5,'30'!I5,'31'!I5) -> 10947.87
A7: TONY KASA | B7: 212326 | C7: 23.307 Dolar + 1.100 Euro | D7: =(Kasa!G6+Kasa!L3)-(Kasa!C6+Kasa!H6+Kasa!M3) -> 44000 | G7: EKLENEN KREDİLER TOPLAMI | H7: =SUM('1'!I7,'2'!I7,'3'!I7,'4'!I7,'5'!I7,'6'!I7,'7'!I7,'8'!I7,'9'!I7,'10'!I7,'11'!I7,'12'!I7,'13'!I7,'14'!I7,'15'!I7,'16'!I7,'17'!I7,'18'!I7,'19'!I7,'20'!I7,'21'!I7,'22'!I7,'23'!I7,'24'!I7,'25'!I7,'26'!I7,'27'!I7,'28'!I7,'29'!I7,'30'!I7,'31'!I7) -> 44000
A8: TS KASA | D8: =(Kasa!G7+Kasa!L4)-(Kasa!C7+Kasa!H7+Kasa!M4) -> 0 | G8: ÖDENEN KREDİLER TOPLAMI | H8: =SUM('1'!I8,'2'!I8,'3'!I8,'4'!I8,'5'!I8,'6'!I8,'7'!I8,'8'!I8,'9'!I8,'10'!I8,'11'!I8,'12'!I8,'13'!I8,'14'!I8,'15'!I8,'16'!I8,'17'!I8,'18'!I8,'19'!I8,'20'!I8,'21'!I8,'22'!I8,'23'!I8,'24'!I8,'25'!I8,'26'!I8,'27'!I8,'28'!I8,'29'!I8,'30'!I8,'31'!I8) -> 0
A9: KARTAL KASA | B9: 100000 | C9: 5.000 Dolar + 3.150 Euro | D9: =(Kasa!G8+Kasa!L5)-(Kasa!C8+Kasa!H8+Kasa!M5) -> 0 | G9: KREDİLER EKLENEN-ÖDENEN FARKI | H9: =SUM('1'!I9,'2'!I9,'3'!I9,'4'!I9,'5'!I9,'6'!I9,'7'!I9,'8'!I9,'9'!I9,'10'!I9,'11'!I9,'12'!I9,'13'!I9,'14'!I9,'15'!I9,'16'!I9,'17'!I9,'18'!I9,'19'!I9,'20'!I9,'21'!I9,'22'!I9,'23'!I9,'24'!I9,'25'!I9,'26'!I9,'27'!I9,'28'!I9,'29'!I9,'30'!I9,'31'!I9) -> 44000
A10: ALEX KASA | D10: =(Kasa!G9+Kasa!L6)-(Kasa!C9+Kasa!H9+Kasa!M6) -> 0 | G10: TOPLAM SİTE YATIRIM | H10: =H4+H7 -> 67443.87
A11: KORAY KASA | D11: =(Kasa!G10+Kasa!L7)-(Kasa!C10+Kasa!H10+Kasa!M7) -> 0 | G11: TOPLAM SİTE ÇEKİMİ | H11: =H5+H8 -> 12496
D12: 0 | G12: ÖDENEN KOMİSYONLAR TOPLAMI | H12: =SUM('1'!I3,'2'!I3,'3'!I3,'4'!I3,'5'!I3,'6'!I3,'7'!I3,'8'!I3,'9'!I3,'10'!I3,'11'!I3,'12'!I3,'13'!I3,'14'!I3,'15'!I3,'16'!I3,'17'!I3,'18'!I3,'19'!I3,'20'!I3,'21'!I3,'22'!I3,'23'!I3,'24'!I3,'25'!I3,'26'!I3,'27'!I3,'28'!I3,'29'!I3,'30'!I3,'31'!I3) -> 2047.4296
D13: 0 | G13: GİDERLER TOPLAMI | H13: =SUM('1'!I13,'2'!I13,'3'!I13,'4'!I13,'5'!I13,'6'!I13,'7'!I13,'8'!I13,'9'!I13,'10'!I13,'11'!I13,'12'!I13,'13'!I13,'14'!I13,'15'!I13,'16'!I13,'17'!I13,'18'!I13,'19'!I13,'20'!I13,'21'!I13,'22'!I13,'23'!I13,'24'!I13,'25'!I13,'26'!I13,'27'!I13,'28'!I13,'29'!I13,'30'!I13,'31'!I13) -> 0
D14: 0
D15: 0 | G15: AYLIK KAR/ZARAR DURUMU | H15: =H10-(H11+H12+H13) -> 52900.44
D16: 0
D17: 0
D18: 0
D19: 0
A20: TOPLAM KASA | D20: =SUM(D4:D19) -> 94082.44

Sheet Kredi
A1: EKİM | B1: OKİCEY | E1: MARDİNLİ47 | H1: KEMALGEZER | K1: MUTOK35 | N1: GÜNLÜK RAPOR | Q1: EKLENEN | R1: ÖDENEN
B2: EKLENEN | C2: ÖDENEN | D2: BAKİYE | E2: EKLENEN | F2: ÖDENEN | G2: BAKİYE | H2: EKLENEN | I2: ÖDENEN | J2: BAKİYE | K2: EKLENEN | L2: ÖDENEN | M2: BAKİYE | N2: EKLENEN | O2: ÖDENEN | P2: FARK | Q2: SAPMA | R2: SAPMA
A3: DEVİR | B3: =SUMIF(Devir!$M$3:$M$13,"OKİCEY",Devir!$K$3:$K$13) -> 720000 | C3: =SUMIF(Devir!$M$3:$M$13,"OKİCEY",Devir!$L$3:$L$13) -> 0 | D3: =B3-C3 -> 720000 | E3: =SUMIF(Devir!$M$3:$M$13,"MARDİNLİ47",Devir!$K$3:$K$13) -> 0 | F3: =SUMIF(Devir!$M$3:$M$13,"MARDİNLİ47",Devir!$L$3:$L$13) -> 0 | G3: =E3-F3 -> 0 | H3: =SUMIF(Devir!$M$3:$M$13,"KEMALGEZER",Devir!$K$3:$K$13) -> 10000 | I3: =SUMIF(Devir!$M$3:$M$13,"KEMALGEZER",Devir!$L$3:$L$13) -> 0 | J3: =H3-I3 -> 10000 | K3: =SUMIF(Devir!$M$3:$M$13,"MUTOK35",Devir!$K$3:$K$13) -> 2000 | L3: =SUMIF(Devir!$M$3:$M$13,"MUTOK35",Devir!$L$3:$L$13) -> 0 | M3: =K3-L3 -> 2000 | N3: =SUM(B3+E3+H3+K3) -> 732000 | O3: =SUM(C3+F3+I3+L3) -> 0 | P3: =N3-O3 -> 732000 | Q3: =(N3)-(Devir!$K$14) -> 0 | R3: =(O3)-(Devir!$L$14) -> 0
A4: 45200 | B4: =SUMIF('1'!$M$3:$M$13,"OKİCEY",'1'!$K$3:$K$13) -> 40000 | C4: =SUMIF('1'!$M$3:$M$13,"OKİCEY",'1'!$L$3:$L$13) -> 0 | D4: =(D3)+(B4-C4) -> 760000 | E4: =SUMIF('1'!$M$3:$M$13,"MARDİNLİ47",'1'!$K$3:$K$13) -> 0 | F4: =SUMIF('1'!$M$3:$M$13,"MARDİNLİ47",'1'!$L$3:$L$13) -> 0 | G4: =(G3)+(E4-F4) -> 0 | H4: =SUMIF('1'!$M$3:$M$13,"KEMALGEZER",'1'!$K$3:$K$13) -> 1000 | I4: =SUMIF('1'!$M$3:$M$13,"KEMALGEZER",'1'!$L$3:$L$13) -> 0 | J4: =(J3)+(H4-I4) -> 11000 | K4: =SUMIF('1'!$M$3:$M$13,"MUTOK35",'1'!$K$3:$K$13) -> 3000 | L4: =SUMIF('1'!$M$3:$M$13,"MUTOK35",'1'!$L$3:$L$13) -> 0 | M4: =(M3)+(K4-L4) -> 5000 | N4: =SUM(B4+E4+H4+K4) -> 44000 | O4: =SUM(C4+F4+I4+L4) -> 0 | P4: =N4-O4 -> 44000 | Q4: =(N4)-('1'!$K$14) -> 0 | R4: =(O4)-('1'!$L$14) -> 0
A5: 45201 | B5: =SUMIF('2'!$M$3:$M$13,"OKİCEY",'2'!$K$3:$K$13) -> 0 | C5: =SUMIF('2'!$M$3:$M$13,"OKİCEY",'2'!$L$3:$L$13) -> 0 | D5: =(D4)+(B5-C5) -> 760000 | E5: =SUMIF('2'!$M$3:$M$13,"MARDİNLİ47",'2'!$K$3:$K$13) -> 0 | F5: =SUMIF('2'!$M$3:$M$13,"MARDİNLİ47",'2'!$L$3:$L$13) -> 0 | G5: =(G4)+(E5-F5) -> 0 | H5: =SUMIF('2'!$M$3:$M$13,"KEMALGEZER",'2'!$K$3:$K$13) -> 0 | I5: =SUMIF('2'!$M$3:$M$13,"KEMALGEZER",'2'!$L$3:$L$13) -> 0 | J5: =(J4)+(H5-I5) -> 11000 | K5: =SUMIF('2'!$M$3:$M$13,"MUTOK35",'2'!$K$3:$K$13) -> 0 | L5: =SUMIF('2'!$M$3:$M$13,"MUTOK35",'2'!$L$3:$L$13) -> 0 | M5: =(M4)+(K5-L5) -> 5000 | N5: =SUM(B5+E5+H5+K5) -> 0 | O5: =SUM(C5+F5+I5+L5) -> 0 | P5: =N5-O5 -> 0 | Q5: =(N5)-('2'!$K$14) -> 0 | R5: =(O5)-('2'!$L$14) -> 0
A6: 45202 | B6: =SUMIF('3'!$M$3:$M$13,"OKİCEY",'3'!$K$3:$K$13) -> 0 | C6: =SUMIF('3'!$M$3:$M$13,"OKİCEY",'3'!$L$3:$L$13) -> 0 | D6: =(D5)+(B6-C6) -> 760000 | E6: =SUMIF('3'!$M$3:$M$13,"MARDİNLİ47",'3'!$K$3:$K$13) -> 0 | F6: =SUMIF('3'!$M$3:$M$13,"MARDİNLİ47",'3'!$L$3:$L$13) -> 0 | G6: =(G5)+(E6-F6) -> 0 | H6: =SUMIF('3'!$M$3:$M$13,"KEMALGEZER",'3'!$K$3:$K$13) -> 0 | I6: =SUMIF('3'!$M$3:$M$13,"KEMALGEZER",'3'!$L$3:$L$13) -> 0 | J6: =(J5)+(H6-I6) -> 11000 | K6: =SUMIF('3'!$M$3:$M$13,"MUTOK35",'3'!$K$3:$K$13) -> 0 | L6: =SUMIF('3'!$M$3:$M$13,"MUTOK35",'3'!$L$3:$L$13) -> 0 | M6: =(M5)+(K6-L6) -> 5000 | N6: =SUM(B6+E6+H6+K6) -> 0 | O6: =SUM(C6+F6+I6+L6) -> 0 | P6: =N6-O6 -> 0 | Q6: =(N6)-('3'!$K$14) -> 0 | R6: =(O6)-('3'!$L$14) -> 0
A7: 45203 | B7: =SUMIF('4'!$M$3:$M$13,"OKİCEY",'4'!$K$3:$K$13) -> 0 | C7: =SUMIF('4'!$M$3:$M$13,"OKİCEY",'4'!$L$3:$L$13) -> 0 | D7: =(D6)+(B7-C7) -> 760000 | E7: =SUMIF('4'!$M$3:$M$13,"MARDİNLİ47",'4'!$K$3:$K$13) -> 0 | F7: =SUMIF('4'!$M$3:$M$13,"MARDİNLİ47",'4'!$L$3:$L$13) -> 0 | G7: =(G6)+(E7-F7) -> 0 | H7: =SUMIF('4'!$M$3:$M$13,"KEMALGEZER",'4'!$K$3:$K$13) -> 0 | I7: =SUMIF('4'!$M$3:$M$13,"KEMALGEZER",'4'!$L$3:$L$13) -> 0 | J7: =(J6)+(H7-I7) -> 11000 | K7: =SUMIF('4'!$M$3:$M$13,"MUTOK35",'4'!$K$3:$K$13) -> 0 | L7: =SUMIF('4'!$M$3:$M$13,"MUTOK35",'4'!$L$3:$L$13) -> 0 | M7: =(M6)+(K7-L7) -> 5000 | N7: =SUM(B7+E7+H7+K7) -> 0 | O7: =SUM(C7+F7+I7+L7) -> 0 | P7: =N7-O7 -> 0 | Q7: =(N7)-('4'!$K$14) -> 0 | R7: =(O7)-('4'!$L$14) -> 0
A8: 45204 | B8: =SUMIF('5'!$M$3:$M$13,"OKİCEY",'5'!$K$3:$K$13) -> 0 | C8: =SUMIF('5'!$M$3:$M$13,"OKİCEY",'5'!$L$3:$L$13) -> 0 | D8: =(D7)+(B8-C8) -> 760000 | E8: =SUMIF('5'!$M$3:$M$13,"MARDİNLİ47",'5'!$K$3:$K$13) -> 0 | F8: =SUMIF('5'!$M$3:$M$13,"MARDİNLİ47",'5'!$L$3:$L$13) -> 0 | G8: =(G7)+(E8-F8) -> 0 | H8: =SUMIF('5'!$M$3:$M$13,"KEMALGEZER",'5'!$K$3:$K$13) -> 0 | I8: =SUMIF('5'!$M$3:$M$13,"KEMALGEZER",'5'!$L$3:$L$13) -> 0 | J8: =(J7)+(H8-I8) -> 11000 | K8: =SUMIF('5'!$M$3:$M$13,"MUTOK35",'5'!$K$3:$K$13) -> 0 | L8: =SUMIF('5'!$M$3:$M$13,"MUTOK35",'5'!$L$3:$L$13) -> 0 | M8: =(M7)+(K8-L8) -> 5000 | N8: =SUM(B8+E8+H8+K8) -> 0 | O8: =SUM(C8+F8+I8+L8) -> 0 | P8: =N8-O8 -> 0 | Q8: =(N8)-('5'!$K$14) -> 0 | R8: =(O8)-('5'!$L$14) -> 0
A9: 45205 | B9: =SUMIF('6'!$M$3:$M$13,"OKİCEY",'6'!$K$3:$K$13) -> 0 | C9: =SUMIF('6'!$M$3:$M$13,"OKİCEY",'6'!$L$3:$L$13) -> 0 | D9: =(D8)+(B9-C9) -> 760000 | E9: =SUMIF('6'!$M$3:$M$13,"MARDİNLİ47",'6'!$K$3:$K$13) -> 0 | F9: =SUMIF('6'!$M$3:$M$13,"MARDİNLİ47",'6'!$L$3:$L$13) -> 0 | G9: =(G8)+(E9-F9) -> 0 | H9: =SUMIF('6'!$M$3:$M$13,"KEMALGEZER",'6'!$K$3:$K$13) -> 0 | I9: =SUMIF('6'!$M$3:$M$13,"KEMALGEZER",'6'!$L$3:$L$13) -> 0 | J9: =(J8)+(H9-I9) -> 11000 | K9: =SUMIF('6'!$M$3:$M$13,"MUTOK35",'6'!$K$3:$K$13) -> 0 | L9: =SUMIF('6'!$M$3:$M$13,"MUTOK35",'6'!$L$3:$L$13) -> 0 | M9: =(M8)+(K9-L9) -> 5000 | N9: =SUM(B9+E9+H9+K9) -> 0 | O9: =SUM(C9+F9+I9+L9) -> 0 | P9: =N9-O9 -> 0 | Q9: =(N9)-('6'!$K$14) -> 0 | R9: =(O9)-('6'!$L$14) -> 0
A10: 45206 | B10: =SUMIF('7'!$M$3:$M$13,"OKİCEY",'7'!$K$3:$K$13) -> 0 | C10: =SUMIF('7'!$M$3:$M$13,"OKİCEY",'7'!$L$3:$L$13) -> 0 | D10: =(D9)+(B10-C10) -> 760000 | E10: =SUMIF('7'!$M$3:$M$13,"MARDİNLİ47",'7'!$K$3:$K$13) -> 0 | F10: =SUMIF('7'!$M$3:$M$13,"MARDİNLİ47",'7'!$L$3:$L$13) -> 0 | G10: =(G9)+(E10-F10) -> 0 | H10: =SUMIF('7'!$M$3:$M$13,"KEMALGEZER",'7'!$K$3:$K$13) -> 0 | I10: =SUMIF('7'!$M$3:$M$13,"KEMALGEZER",'7'!$L$3:$L$13) -> 0 | J10: =(J9)+(H10-I10) -> 11000 | K10: =SUMIF('7'!$M$3:$M$13,"MUTOK35",'7'!$K$3:$K$13) -> 0 | L10: =SUMIF('7'!$M$3:$M$13,"MUTOK35",'7'!$L$3:$L$13) -> 0 | M10: =(M9)+(K10-L10) -> 5000 | N10: =SUM(B10+E10+H10+K10) -> 0 | O10: =SUM(C10+F10+I10+L10) -> 0 | P10: =N10-O10 -> 0 | Q10: =(N10)-('7'!$K$14) -> 0 | R10: =(O10)-('7'!$L$14) -> 0
A11: 45207 | B11: =SUMIF('8'!$M$3:$M$13,"OKİCEY",'8'!$K$3:$K$13) -> 0 | C11: =SUMIF('8'!$M$3:$M$13,"OKİCEY",'8'!$L$3:$L$13) -> 0 | D11: =(D10)+(B11-C11) -> 760000 | E11: =SUMIF('8'!$M$3:$M$13,"MARDİNLİ47",'8'!$K$3:$K$13) -> 0 | F11: =SUMIF('8'!$M$3:$M$13,"MARDİNLİ47",'8'!$L$3:$L$13) -> 0 | G11: =(G10)+(E11-F11) -> 0 | H11: =SUMIF('8'!$M$3:$M$13,"KEMALGEZER",'8'!$K$3:$K$13) -> 0 | I11: =SUMIF('8'!$M$3:$M$13,"KEMALGEZER",'8'!$L$3:$L$13) -> 0 | J11: =(J10)+(H11-I11) -> 11000 | K11: =SUMIF('8'!$M$3:$M$13,"MUTOK35",'8'!$K$3:$K$13) -> 0 | L11: =SUMIF('8'!$M$3:$M$13,"MUTOK35",'8'!$L$3:$L$13) -> 0 | M11: =(M10)+(K11-L11) -> 5000 | N11: =SUM(B11+E11+H11+K11) -> 0 | O11: =SUM(C11+F11+I11+L11) -> 0 | P11: =N11-O11 -> 0 | Q11: =(N11)-('8'!$K$14) -> 0 | R11: =(O11)-('8'!$L$14) -> 0
A12: 45208 | B12: =SUMIF('9'!$M$3:$M$13,"OKİCEY",'9'!$K$3:$K$13) -> 0 | C12: =SUMIF('9'!$M$3:$M$13,"OKİCEY",'9'!$L$3:$L$13) -> 0 | D12: =(D11)+(B12-C12) -> 760000 | E12: =SUMIF('9'!$M$3:$M$13,"MARDİNLİ47",'9'!$K$3:$K$13) -> 0 | F12: =SUMIF('9'!$M$3:$M$13,"MARDİNLİ47",'9'!$L$3:$L$13) -> 0 | G12: =(G11)+(E12-F12) -> 0 | H12: =SUMIF('9'!$M$3:$M$13,"KEMALGEZER",'9'!$K$3:$K$13) -> 0 | I12: =SUMIF('9'!$M$3:$M$13,"KEMALGEZER",'9'!$L$3:$L$13) -> 0 | J12: =(J11)+(H12-I12) -> 11000 | K12: =SUMIF('9'!$M$3:$M$13,"MUTOK35",'9'!$K$3:$K$13) -> 0 | L12: =SUMIF('9'!$M$3:$M$13,"MUTOK35",'9'!$L$3:$L$13) -> 0 | M12: =(M11)+(K12-L12) -> 5000 | N12: =SUM(B12+E12+H12+K12) -> 0 | O12: =SUM(C12+F12+I12+L12) -> 0 | P12: =N12-O12 -> 0 | Q12: =(N12)-('9'!$K$14) -> 0 | R12: =(O12)-('9'!$L$14) -> 0
A13: 45209 | B13: =SUMIF('10'!$M$3:$M$13,"OKİCEY",'10'!$K$3:$K$13) -> 0 | C13: =SUMIF('10'!$M$3:$M$13,"OKİCEY",'10'!$L$3:$L$13) -> 0 | D13: =(D12)+(B13-C13) -> 760000 | E13: =SUMIF('10'!$M$3:$M$13,"MARDİNLİ47",'10'!$K$3:$K$13) -> 0 | F13: =SUMIF('10'!$M$3:$M$13,"MARDİNLİ47",'10'!$L$3:$L$13) -> 0 | G13: =(G12)+(E13-F13) -> 0 | H13: =SUMIF('10'!$M$3:$M$13,"KEMALGEZER",'10'!$K$3:$K$13) -> 0 | I13: =SUMIF('10'!$M$3:$M$13,"KEMALGEZER",'10'!$L$3:$L$13) -> 0 | J13: =(J12)+(H13-I13) -> 11000 | K13: =SUMIF('10'!$M$3:$M$13,"MUTOK35",'10'!$K$3:$K$13) -> 0 | L13: =SUMIF('10'!$M$3:$M$13,"MUTOK35",'10'!$L$3:$L$13) -> 0 | M13: =(M12)+(K13-L13) -> 5000 | N13: =SUM(B13+E13+H13+K13) -> 0 | O13: =SUM(C13+F13+I13+L13) -> 0 | P13: =N13-O13 -> 0 | Q13: =(N13)-('10'!$K$14) -> 0 | R13: =(O13)-('10'!$L$14) -> 0
A14: 45210 | B14: =SUMIF('11'!$M$3:$M$13,"OKİCEY",'11'!$K$3:$K$13) -> 0 | C14: =SUMIF('11'!$M$3:$M$13,"OKİCEY",'11'!$L$3:$L$13) -> 0 | D14: =(D13)+(B14-C14) -> 760000 | E14: =SUMIF('11'!$M$3:$M$13,"MARDİNLİ47",'11'!$K$3:$K$13) -> 0 | F14: =SUMIF('11'!$M$3:$M$13,"MARDİNLİ47",'11'!$L$3:$L$13) -> 0 | G14: =(G13)+(E14-F14) -> 0 | H14: =SUMIF('11'!$M$3:$M$13,"KEMALGEZER",'11'!$K$3:$K$13) -> 0 | I14: =SUMIF('11'!$M$3:$M$13,"KEMALGEZER",'11'!$L$3:$L$13) -> 0 | J14: =(J13)+(H14-I14) -> 11000 | K14: =SUMIF('11'!$M$3:$M$13,"MUTOK35",'11'!$K$3:$K$13) -> 0 | L14: =SUMIF('11'!$M$3:$M$13,"MUTOK35",'11'!$L$3:$L$13) -> 0 | M14: =(M13)+(K14-L14) -> 5000 | N14: =SUM(B14+E14+H14+K14) -> 0 | O14: =SUM(C14+F14+I14+L14) -> 0 | P14: =N14-O14 -> 0 | Q14: =(N14)-('11'!$K$14) -> 0 | R14: =(O14)-('11'!$L$14) -> 0
A15: 45211 | B15: =SUMIF('12'!$M$3:$M$13,"OKİCEY",'12'!$K$3:$K$13) -> 0 | C15: =SUMIF('12'!$M$3:$M$13,"OKİCEY",'12'!$L$3:$L$13) -> 0 | D15: =(D14)+(B15-C15) -> 760000 | E15: =SUMIF('12'!$M$3:$M$13,"MARDİNLİ47",'12'!$K$3:$K$13) -> 0 | F15: =SUMIF('12'!$M$3:$M$13,"MARDİNLİ47",'12'!$L$3:$L$13) -> 0 | G15: =(G14)+(E15-F15) -> 0 | H15: =SUMIF('12'!$M$3:$M$13,"KEMALGEZER",'12'!$K$3:$K$13) -> 0 | I15: =SUMIF('12'!$M$3:$M$13,"KEMALGEZER",'12'!$L$3:$L$13) -> 0 | J15: =(J14)+(H15-I15) -> 11000 | K15: =SUMIF('12'!$M$3:$M$13,"MUTOK35",'12'!$K$3:$K$13) -> 0 | L15: =SUMIF('12'!$M$3:$M$13,"MUTOK35",'12'!$L$3:$L$13) -> 0 | M15: =(M14)+(K15-L15) -> 5000 | N15: =SUM(B15+E15+H15+K15) -> 0 | O15: =SUM(C15+F15+I15+L15) -> 0 | P15: =N15-O15 -> 0 | Q15: =(N15)-('12'!$K$14) -> 0 | R15: =(O15)-('12'!$L$14) -> 0
A16: 45212 | B16: =SUMIF('13'!$M$3:$M$13,"OKİCEY",'13'!$K$3:$K$13) -> 0 | C16: =SUMIF('13'!$M$3:$M$13,"OKİCEY",'13'!$L$3:$L$13) -> 0 | D16: =(D15)+(B16-C16) -> 760000 | E16: =SUMIF('13'!$M$3:$M$13,"MARDİNLİ47",'13'!$K$3:$K$13) -> 0 | F16: =SUMIF('13'!$M$3:$M$13,"MARDİNLİ47",'13'!$L$3:$L$13) -> 0 | G16: =(G15)+(E16-F16) -> 0 | H16: =SUMIF('13'!$M$3:$M$13,"KEMALGEZER",'13'!$K$3:$K$13) -> 0 | I16: =SUMIF('13'!$M$3:$M$13,"KEMALGEZER",'13'!$L$3:$L$13) -> 0 | J16: =(J15)+(H16-I16) -> 11000 | K16: =SUMIF('13'!$M$3:$M$13,"MUTOK35",'13'!$K$3:$K$13) -> 0 | L16: =SUMIF('13'!$M$3:$M$13,"MUTOK35",'13'!$L$3:$L$13) -> 0 | M16: =(M15)+(K16-L16) -> 5000 | N16: =SUM(B16+E16+H16+K16) -> 0 | O16: =SUM(C16+F16+I16+L16) -> 0 | P16: =N16-O16 -> 0 | Q16: =(N16)-('13'!$K$14) -> 0 | R16: =(O16)-('13'!$L$14) -> 0
A17: 45213 | B17: =SUMIF('14'!$M$3:$M$13,"OKİCEY",'14'!$K$3:$K$13) -> 0 | C17: =SUMIF('14'!$M$3:$M$13,"OKİCEY",'14'!$L$3:$L$13) -> 0 | D17: =(D16)+(B17-C17) -> 760000 | E17: =SUMIF('14'!$M$3:$M$13,"MARDİNLİ47",'14'!$K$3:$K$13) -> 0 | F17: =SUMIF('14'!$M$3:$M$13,"MARDİNLİ47",'14'!$L$3:$L$13) -> 0 | G17: =(G16)+(E17-F17) -> 0 | H17: =SUMIF('14'!$M$3:$M$13,"KEMALGEZER",'14'!$K$3:$K$13) -> 0 | I17: =SUMIF('14'!$M$3:$M$13,"KEMALGEZER",'14'!$L$3:$L$13) -> 0 | J17: =(J16)+(H17-I17) -> 11000 | K17: =SUMIF('14'!$M$3:$M$13,"MUTOK35",'14'!$K$3:$K$13) -> 0 | L17: =SUMIF('14'!$M$3:$M$13,"MUTOK35",'14'!$L$3:$L$13) -> 0 | M17: =(M16)+(K17-L17) -> 5000 | N17: =SUM(B17+E17+H17+K17) -> 0 | O17: =SUM(C17+F17+I17+L17) -> 0 | P17: =N17-O17 -> 0 | Q17: =(N17)-('14'!$K$14) -> 0 | R17: =(O17)-('14'!$L$14) -> 0
A18: 45214 | B18: =SUMIF('15'!$M$3:$M$13,"OKİCEY",'15'!$K$3:$K$13) -> 0 | C18: =SUMIF('15'!$M$3:$M$13,"OKİCEY",'15'!$L$3:$L$13) -> 0 | D18: =(D17)+(B18-C18) -> 760000 | E18: =SUMIF('15'!$M$3:$M$13,"MARDİNLİ47",'15'!$K$3:$K$13) -> 0 | F18: =SUMIF('15'!$M$3:$M$13,"MARDİNLİ47",'15'!$L$3:$L$13) -> 0 | G18: =(G17)+(E18-F18) -> 0 | H18: =SUMIF('15'!$M$3:$M$13,"KEMALGEZER",'15'!$K$3:$K$13) -> 0 | I18: =SUMIF('15'!$M$3:$M$13,"KEMALGEZER",'15'!$L$3:$L$13) -> 0 | J18: =(J17)+(H18-I18) -> 11000 | K18: =SUMIF('15'!$M$3:$M$13,"MUTOK35",'15'!$K$3:$K$13) -> 0 | L18: =SUMIF('15'!$M$3:$M$13,"MUTOK35",'15'!$L$3:$L$13) -> 0 | M18: =(M17)+(K18-L18) -> 5000 | N18: =SUM(B18+E18+H18+K18) -> 0 | O18: =SUM(C18+F18+I18+L18) -> 0 | P18: =N18-O18 -> 0 | Q18: =(N18)-('15'!$K$14) -> 0 | R18: =(O18)-('15'!$L$14) -> 0
A19: 45215 | B19: =SUMIF('16'!$M$3:$M$13,"OKİCEY",'16'!$K$3:$K$13) -> 0 | C19: =SUMIF('16'!$M$3:$M$13,"OKİCEY",'16'!$L$3:$L$13) -> 0 | D19: =(D18)+(B19-C19) -> 760000 | E19: =SUMIF('16'!$M$3:$M$13,"MARDİNLİ47",'16'!$K$3:$K$13) -> 0 | F19: =SUMIF('16'!$M$3:$M$13,"MARDİNLİ47",'16'!$L$3:$L$13) -> 0 | G19: =(G18)+(E19-F19) -> 0 | H19: =SUMIF('16'!$M$3:$M$13,"KEMALGEZER",'16'!$K$3:$K$13) -> 0 | I19: =SUMIF('16'!$M$3:$M$13,"KEMALGEZER",'16'!$L$3:$L$13) -> 0 | J19: =(J18)+(H19-I19) -> 11000 | K19: =SUMIF('16'!$M$3:$M$13,"MUTOK35",'16'!$K$3:$K$13) -> 0 | L19: =SUMIF('16'!$M$3:$M$13,"MUTOK35",'16'!$L$3:$L$13) -> 0 | M19: =(M18)+(K19-L19) -> 5000 | N19: =SUM(B19+E19+H19+K19) -> 0 | O19: =SUM(C19+F19+I19+L19) -> 0 | P19: =N19-O19 -> 0 | Q19: =(N19)-('16'!$K$14) -> 0 | R19: =(O19)-('16'!$L$14) -> 0
A20: 45216 | B20: =SUMIF('17'!$M$3:$M$13,"OKİCEY",'17'!$K$3:$K$13) -> 0 | C20: =SUMIF('17'!$M$3:$M$13,"OKİCEY",'17'!$L$3:$L$13) -> 0 | D20: =(D19)+(B20-C20) -> 760000 | E20: =SUMIF('17'!$M$3:$M$13,"MARDİNLİ47",'17'!$K$3:$K$13) -> 0 | F20: =SUMIF('17'!$M$3:$M$13,"MARDİNLİ47",'17'!$L$3:$L$13) -> 0 | G20: =(G19)+(E20-F20) -> 0 | H20: =SUMIF('17'!$M$3:$M$13,"KEMALGEZER",'17'!$K$3:$K$13) -> 0 | I20: =SUMIF('17'!$M$3:$M$13,"KEMALGEZER",'17'!$L$3:$L$13) -> 0 | J20: =(J19)+(H20-I20) -> 11000 | K20: =SUMIF('17'!$M$3:$M$13,"MUTOK35",'17'!$K$3:$K$13) -> 0 | L20: =SUMIF('17'!$M$3:$M$13,"MUTOK35",'17'!$L$3:$L$13) -> 0 | M20: =(M19)+(K20-L20) -> 5000 | N20: =SUM(B20+E20+H20+K20) -> 0 | O20: =SUM(C20+F20+I20+L20) -> 0 | P20: =N20-O20 -> 0 | Q20: =(N20)-('17'!$K$14) -> 0 | R20: =(O20)-('17'!$L$14) -> 0
A21: 45217 | B21: =SUMIF('18'!$M$3:$M$13,"OKİCEY",'18'!$K$3:$K$13) -> 0 | C21: =SUMIF('18'!$M$3:$M$13,"OKİCEY",'18'!$L$3:$L$13) -> 0 | D21: =(D20)+(B21-C21) -> 760000 | E21: =SUMIF('18'!$M$3:$M$13,"MARDİNLİ47",'18'!$K$3:$K$13) -> 0 | F21: =SUMIF('18'!$M$3:$M$13,"MARDİNLİ47",'18'!$L$3:$L$13) -> 0 | G21: =(G20)+(E21-F21) -> 0 | H21: =SUMIF('18'!$M$3:$M$13,"KEMALGEZER",'18'!$K$3:$K$13) -> 0 | I21: =SUMIF('18'!$M$3:$M$13,"KEMALGEZER",'18'!$L$3:$L$13) -> 0 | J21: =(J20)+(H21-I21) -> 11000 | K21: =SUMIF('18'!$M$3:$M$13,"MUTOK35",'18'!$K$3:$K$13) -> 0 | L21: =SUMIF('18'!$M$3:$M$13,"MUTOK35",'18'!$L$3:$L$13) -> 0 | M21: =(M20)+(K21-L21) -> 5000 | N21: =SUM(B21+E21+H21+K21) -> 0 | O21: =SUM(C21+F21+I21+L21) -> 0 | P21: =N21-O21 -> 0 | Q21: =(N21)-('18'!$K$14) -> 0 | R21: =(O21)-('18'!$L$14) -> 0
A22: 45218 | B22: =SUMIF('19'!$M$3:$M$13,"OKİCEY",'19'!$K$3:$K$13) -> 0 | C22: =SUMIF('19'!$M$3:$M$13,"OKİCEY",'19'!$L$3:$L$13) -> 0 | D22: =(D21)+(B22-C22) -> 760000 | E22: =SUMIF('19'!$M$3:$M$13,"MARDİNLİ47",'19'!$K$3:$K$13) -> 0 | F22: =SUMIF('19'!$M$3:$M$13,"MARDİNLİ47",'19'!$L$3:$L$13) -> 0 | G22: =(G21)+(E22-F22) -> 0 | H22: =SUMIF('19'!$M$3:$M$13,"KEMALGEZER",'19'!$K$3:$K$13) -> 0 | I22: =SUMIF('19'!$M$3:$M$13,"KEMALGEZER",'19'!$L$3:$L$13) -> 0 | J22: =(J21)+(H22-I22) -> 11000 | K22: =SUMIF('19'!$M$3:$M$13,"MUTOK35",'19'!$K$3:$K$13) -> 0 | L22: =SUMIF('19'!$M$3:$M$13,"MUTOK35",'19'!$L$3:$L$13) -> 0 | M22: =(M21)+(K22-L22) -> 5000 | N22: =SUM(B22+E22+H22+K22) -> 0 | O22: =SUM(C22+F22+I22+L22) -> 0 | P22: =N22-O22 -> 0 | Q22: =(N22)-('19'!$K$14) -> 0 | R22: =(O22)-('19'!$L$14) -> 0
A23: 45219 | B23: =SUMIF('20'!$M$3:$M$13,"OKİCEY",'20'!$K$3:$K$13) -> 0 | C23: =SUMIF('20'!$M$3:$M$13,"OKİCEY",'20'!$L$3:$L$13) -> 0 | D23: =(D22)+(B23-C23) -> 760000 | E23: =SUMIF('20'!$M$3:$M$13,"MARDİNLİ47",'20'!$K$3:$K$13) -> 0 | F23: =SUMIF('20'!$M$3:$M$13,"MARDİNLİ47",'20'!$L$3:$L$13) -> 0 | G23: =(G22)+(E23-F23) -> 0 | H23: =SUMIF('20'!$M$3:$M$13,"KEMALGEZER",'20'!$K$3:$K$13) -> 0 | I23: =SUMIF('20'!$M$3:$M$13,"KEMALGEZER",'20'!$L$3:$L$13) -> 0 | J23: =(J22)+(H23-I23) -> 11000 | K23: =SUMIF('20'!$M$3:$M$13,"MUTOK35",'20'!$K$3:$K$13) -> 0 | L23: =SUMIF('20'!$M$3:$M$13,"MUTOK35",'20'!$L$3:$L$13) -> 0 | M23: =(M22)+(K23-L23) -> 5000 | N23: =SUM(B23+E23+H23+K23) -> 0 | O23: =SUM(C23+F23+I23+L23) -> 0 | P23: =N23-O23 -> 0 | Q23: =(N23)-('20'!$K$14) -> 0 | R23: =(O23)-('20'!$L$14) -> 0
A24: 45220 | B24: =SUMIF('21'!$M$3:$M$13,"OKİCEY",'21'!$K$3:$K$13) -> 0 | C24: =SUMIF('21'!$M$3:$M$13,"OKİCEY",'21'!$L$3:$L$13) -> 0 | D24: =(D23)+(B24-C24) -> 760000 | E24: =SUMIF('21'!$M$3:$M$13,"MARDİNLİ47",'21'!$K$3:$K$13) -> 0 | F24: =SUMIF('21'!$M$3:$M$13,"MARDİNLİ47",'21'!$L$3:$L$13) -> 0 | G24: =(G23)+(E24-F24) -> 0 | H24: =SUMIF('21'!$M$3:$M$13,"KEMALGEZER",'21'!$K$3:$K$13) -> 0 | I24: =SUMIF('21'!$M$3:$M$13,"KEMALGEZER",'21'!$L$3:$L$13) -> 0 | J24: =(J23)+(H24-I24) -> 11000 | K24: =SUMIF('21'!$M$3:$M$13,"MUTOK35",'21'!$K$3:$K$13) -> 0 | L24: =SUMIF('21'!$M$3:$M$13,"MUTOK35",'21'!$L$3:$L$13) -> 0 | M24: =(M23)+(K24-L24) -> 5000 | N24: =SUM(B24+E24+H24+K24) -> 0 | O24: =SUM(C24+F24+I24+L24) -> 0 | P24: =N24-O24 -> 0 | Q24: =(N24)-('21'!$K$14) -> 0 | R24: =(O24)-('21'!$L$14) -> 0
A25: 45221 | B25: =SUMIF('22'!$M$3:$M$13,"OKİCEY",'22'!$K$3:$K$13) -> 0 | C25: =SUMIF('22'!$M$3:$M$13,"OKİCEY",'22'!$L$3:$L$13) -> 0 | D25: =(D24)+(B25-C25) -> 760000 | E25: =SUMIF('22'!$M$3:$M$13,"MARDİNLİ47",'22'!$K$3:$K$13) -> 0 | F25: =SUMIF('22'!$M$3:$M$13,"MARDİNLİ47",'22'!$L$3:$L$13) -> 0 | G25: =(G24)+(E25-F25) -> 0 | H25: =SUMIF('22'!$M$3:$M$13,"KEMALGEZER",'22'!$K$3:$K$13) -> 0 | I25: =SUMIF('22'!$M$3:$M$13,"KEMALGEZER",'22'!$L$3:$L$13) -> 0 | J25: =(J24)+(H25-I25) -> 11000 | K25: =SUMIF('22'!$M$3:$M$13,"MUTOK35",'22'!$K$3:$K$13) -> 0 | L25: =SUMIF('22'!$M$3:$M$13,"MUTOK35",'22'!$L$3:$L$13) -> 0 | M25: =(M24)+(K25-L25) -> 5000 | N25: =SUM(B25+E25+H25+K25) -> 0 | O25: =SUM(C25+F25+I25+L25) -> 0 | P25: =N25-O25 -> 0 | Q25: =(N25)-('22'!$K$14) -> 0 | R25: =(O25)-('22'!$L$14) -> 0
A26: 45222 | B26: =SUMIF('23'!$M$3:$M$13,"OKİCEY",'23'!$K$3:$K$13) -> 0 | C26: =SUMIF('23'!$M$3:$M$13,"OKİCEY",'23'!$L$3:$L$13) -> 0 | D26: =(D25)+(B26-C26) -> 760000 | E26: =SUMIF('23'!$M$3:$M$13,"MARDİNLİ47",'23'!$K$3:$K$13) -> 0 | F26: =SUMIF('23'!$M$3:$M$13,"MARDİNLİ47",'23'!$L$3:$L$13) -> 0 | G26: =(G25)+(E26-F26) -> 0 | H26: =SUMIF('23'!$M$3:$M$13,"KEMALGEZER",'23'!$K$3:$K$13) -> 0 | I26: =SUMIF('23'!$M$3:$M$13,"KEMALGEZER",'23'!$L$3:$L$13) -> 0 | J26: =(J25)+(H26-I26) -> 11000 | K26: =SUMIF('23'!$M$3:$M$13,"MUTOK35",'23'!$K$3:$K$13) -> 0 | L26: =SUMIF('23'!$M$3:$M$13,"MUTOK35",'23'!$L$3:$L$13) -> 0 | M26: =(M25)+(K26-L26) -> 5000 | N26: =SUM(B26+E26+H26+K26) -> 0 | O26: =SUM(C26+F26+I26+L26) -> 0 | P26: =N26-O26 -> 0 | Q26: =(N26)-('23'!$K$14) -> 0 | R26: =(O26)-('23'!$L$14) -> 0
A27: 45223 | B27: =SUMIF('24'!$M$3:$M$13,"OKİCEY",'24'!$K$3:$K$13) -> 0 | C27: =SUMIF('24'!$M$3:$M$13,"OKİCEY",'24'!$L$3:$L$13) -> 0 | D27: =(D26)+(B27-C27) -> 760000 | E27: =SUMIF('24'!$M$3:$M$13,"MARDİNLİ47",'24'!$K$3:$K$13) -> 0 | F27: =SUMIF('24'!$M$3:$M$13,"MARDİNLİ47",'24'!$L$3:$L$13) -> 0 | G27: =(G26)+(E27-F27) -> 0 | H27: =SUMIF('24'!$M$3:$M$13,"KEMALGEZER",'24'!$K$3:$K$13) -> 0 | I27: =SUMIF('24'!$M$3:$M$13,"KEMALGEZER",'24'!$L$3:$L$13) -> 0 | J27: =(J26)+(H27-I27) -> 11000 | K27: =SUMIF('24'!$M$3:$M$13,"MUTOK35",'24'!$K$3:$K$13) -> 0 | L27: =SUMIF('24'!$M$3:$M$13,"MUTOK35",'24'!$L$3:$L$13) -> 0 | M27: =(M26)+(K27-L27) -> 5000 | N27: =SUM(B27+E27+H27+K27) -> 0 | O27: =SUM(C27+F27+I27+L27) -> 0 | P27: =N27-O27 -> 0 | Q27: =(N27)-('24'!$K$14) -> 0 | R27: =(O27)-('24'!$L$14) -> 0
A28: 45224 | B28: =SUMIF('25'!$M$3:$M$13,"OKİCEY",'25'!$K$3:$K$13) -> 0 | C28: =SUMIF('25'!$M$3:$M$13,"OKİCEY",'25'!$L$3:$L$13) -> 0 | D28: =(D27)+(B28-C28) -> 760000 | E28: =SUMIF('25'!$M$3:$M$13,"MARDİNLİ47",'25'!$K$3:$K$13) -> 0 | F28: =SUMIF('25'!$M$3:$M$13,"MARDİNLİ47",'25'!$L$3:$L$13) -> 0 | G28: =(G27)+(E28-F28) -> 0 | H28: =SUMIF('25'!$M$3:$M$13,"KEMALGEZER",'25'!$K$3:$K$13) -> 0 | I28: =SUMIF('25'!$M$3:$M$13,"KEMALGEZER",'25'!$L$3:$L$13) -> 0 | J28: =(J27)+(H28-I28) -> 11000 | K28: =SUMIF('25'!$M$3:$M$13,"MUTOK35",'25'!$K$3:$K$13) -> 0 | L28: =SUMIF('25'!$M$3:$M$13,"MUTOK35",'25'!$L$3:$L$13) -> 0 | M28: =(M27)+(K28-L28) -> 5000 | N28: =SUM(B28+E28+H28+K28) -> 0 | O28: =SUM(C28+F28+I28+L28) -> 0 | P28: =N28-O28 -> 0 | Q28: =(N28)-('25'!$K$14) -> 0 | R28: =(O28)-('25'!$L$14) -> 0
A29: 45225 | B29: =SUMIF('26'!$M$3:$M$13,"OKİCEY",'26'!$K$3:$K$13) -> 0 | C29: =SUMIF('26'!$M$3:$M$13,"OKİCEY",'26'!$L$3:$L$13) -> 0 | D29: =(D28)+(B29-C29) -> 760000 | E29: =SUMIF('26'!$M$3:$M$13,"MARDİNLİ47",'26'!$K$3:$K$13) -> 0 | F29: =SUMIF('26'!$M$3:$M$13,"MARDİNLİ47",'26'!$L$3:$L$13) -> 0 | G29: =(G28)+(E29-F29) -> 0 | H29: =SUMIF('26'!$M$3:$M$13,"KEMALGEZER",'26'!$K$3:$K$13) -> 0 | I29: =SUMIF('26'!$M$3:$M$13,"KEMALGEZER",'26'!$L$3:$L$13) -> 0 | J29: =(J28)+(H29-I29) -> 11000 | K29: =SUMIF('26'!$M$3:$M$13,"MUTOK35",'26'!$K$3:$K$13) -> 0 | L29: =SUMIF('26'!$M$3:$M$13,"MUTOK35",'26'!$L$3:$L$13) -> 0 | M29: =(M28)+(K29-L29) -> 5000 | N29: =SUM(B29+E29+H29+K29) -> 0 | O29: =SUM(C29+F29+I29+L29) -> 0 | P29: =N29-O29 -> 0 | Q29: =(N29)-('26'!$K$14) -> 0 | R29: =(O29)-('26'!$L$14) -> 0
A30: 45226 | B30: =SUMIF('27'!$M$3:$M$13,"OKİCEY",'27'!$K$3:$K$13) -> 0 | C30: =SUMIF('27'!$M$3:$M$13,"OKİCEY",'27'!$L$3:$L$13) -> 0 | D30: =(D29)+(B30-C30) -> 760000 | E30: =SUMIF('27'!$M$3:$M$13,"MARDİNLİ47",'27'!$K$3:$K$13) -> 0 | F30: =SUMIF('27'!$M$3:$M$13,"MARDİNLİ47",'27'!$L$3:$L$13) -> 0 | G30: =(G29)+(E30-F30) -> 0 | H30: =SUMIF('27'!$M$3:$M$13,"KEMALGEZER",'27'!$K$3:$K$13) -> 0 | I30: =SUMIF('27'!$M$3:$M$13,"KEMALGEZER",'27'!$L$3:$L$13) -> 0 | J30: =(J29)+(H30-I30) -> 11000 | K30: =SUMIF('27'!$M$3:$M$13,"MUTOK35",'27'!$K$3:$K$13) -> 0 | L30: =SUMIF('27'!$M$3:$M$13,"MUTOK35",'27'!$L$3:$L$13) -> 0 | M30: =(M29)+(K30-L30) -> 5000 | N30: =SUM(B30+E30+H30+K30) -> 0 | O30: =SUM(C30+F30+I30+L30) -> 0 | P30: =N30-O30 -> 0 | Q30: =(N30)-('27'!$K$14) -> 0 | R30: =(O30)-('27'!$L$14) -> 0
A31: 45227 | B31: =SUMIF('28'!$M$3:$M$13,"OKİCEY",'28'!$K$3:$K$13) -> 0 | C31: =SUMIF('28'!$M$3:$M$13,"OKİCEY",'28'!$L$3:$L$13) -> 0 | D31: =(D30)+(B31-C31) -> 760000 | E31: =SUMIF('28'!$M$3:$M$13,"MARDİNLİ47",'28'!$K$3:$K$13) -> 0 | F31: =SUMIF('28'!$M$3:$M$13,"MARDİNLİ47",'28'!$L$3:$L$13) -> 0 | G31: =(G30)+(E31-F31) -> 0 | H31: =SUMIF('28'!$M$3:$M$13,"KEMALGEZER",'28'!$K$3:$K$13) -> 0 | I31: =SUMIF('28'!$M$3:$M$13,"KEMALGEZER",'28'!$L$3:$L$13) -> 0 | J31: =(J30)+(H31-I31) -> 11000 | K31: =SUMIF('28'!$M$3:$M$13,"MUTOK35",'28'!$K$3:$K$13) -> 0 | L31: =SUMIF('28'!$M$3:$M$13,"MUTOK35",'28'!$L$3:$L$13) -> 0 | M31: =(M30)+(K31-L31) -> 5000 | N31: =SUM(B31+E31+H31+K31) -> 0 | O31: =SUM(C31+F31+I31+L31) -> 0 | P31: =N31-O31 -> 0 | Q31: =(N31)-('28'!$K$14) -> 0 | R31: =(O31)-('28'!$L$14) -> 0
A32: 45228 | B32: =SUMIF('29'!$M$3:$M$13,"OKİCEY",'29'!$K$3:$K$13) -> 0 | C32: =SUMIF('29'!$M$3:$M$13,"OKİCEY",'29'!$L$3:$L$13) -> 0 | D32: =(D31)+(B32-C32) -> 760000 | E32: =SUMIF('29'!$M$3:$M$13,"MARDİNLİ47",'29'!$K$3:$K$13) -> 0 | F32: =SUMIF('29'!$M$3:$M$13,"MARDİNLİ47",'29'!$L$3:$L$13) -> 0 | G32: =(G31)+(E32-F32) -> 0 | H32: =SUMIF('29'!$M$3:$M$13,"KEMALGEZER",'29'!$K$3:$K$13) -> 0 | I32: =SUMIF('29'!$M$3:$M$13,"KEMALGEZER",'29'!$L$3:$L$13) -> 0 | J32: =(J31)+(H32-I32) -> 11000 | K32: =SUMIF('29'!$M$3:$M$13,"MUTOK35",'29'!$K$3:$K$13) -> 0 | L32: =SUMIF('29'!$M$3:$M$13,"MUTOK35",'29'!$L$3:$L$13) -> 0 | M32: =(M31)+(K32-L32) -> 5000 | N32: =SUM(B32+E32+H32+K32) -> 0 | O32: =SUM(C32+F32+I32+L32) -> 0 | P32: =N32-O32 -> 0 | Q32: =(N32)-('29'!$K$14) -> 0 | R32: =(O32)-('29'!$L$14) -> 0
A33: 45229 | B33: =SUMIF('30'!$M$3:$M$13,"OKİCEY",'30'!$K$3:$K$13) -> 0 | C33: =SUMIF('30'!$M$3:$M$13,"OKİCEY",'30'!$L$3:$L$13) -> 0 | D33: =(D32)+(B33-C33) -> 760000 | E33: =SUMIF('30'!$M$3:$M$13,"MARDİNLİ47",'30'!$K$3:$K$13) -> 0 | F33: =SUMIF('30'!$M$3:$M$13,"MARDİNLİ47",'30'!$L$3:$L$13) -> 0 | G33: =(G32)+(E33-F33) -> 0 | H33: =SUMIF('30'!$M$3:$M$13,"KEMALGEZER",'30'!$K$3:$K$13) -> 0 | I33: =SUMIF('30'!$M$3:$M$13,"KEMALGEZER",'30'!$L$3:$L$13) -> 0 | J33: =(J32)+(H33-I33) -> 11000 | K33: =SUMIF('30'!$M$3:$M$13,"MUTOK35",'30'!$K$3:$K$13) -> 0 | L33: =SUMIF('30'!$M$3:$M$13,"MUTOK35",'30'!$L$3:$L$13) -> 0 | M33: =(M32)+(K33-L33) -> 5000 | N33: =SUM(B33+E33+H33+K33) -> 0 | O33: =SUM(C33+F33+I33+L33) -> 0 | P33: =N33-O33 -> 0 | Q33: =(N33)-('30'!$K$14) -> 0 | R33: =(O33)-('30'!$L$14) -> 0
A34: 45230 | B34: =SUMIF('31'!$M$3:$M$13,"OKİCEY",'31'!$K$3:$K$13) -> 0 | C34: =SUMIF('31'!$M$3:$M$13,"OKİCEY",'31'!$L$3:$L$13) -> 0 | D34: =(D33)+(B34-C34) -> 760000 | E34: =SUMIF('31'!$M$3:$M$13,"MARDİNLİ47",'31'!$K$3:$K$13) -> 0 | F34: =SUMIF('31'!$M$3:$M$13,"MARDİNLİ47",'31'!$L$3:$L$13) -> 0 | G34: =(G33)+(E34-F34) -> 0 | H34: =SUMIF('31'!$M$3:$M$13,"KEMALGEZER",'31'!$K$3:$K$13) -> 0 | I34: =SUMIF('31'!$M$3:$M$13,"KEMALGEZER",'31'!$L$3:$L$13) -> 0 | J34: =(J33)+(H34-I34) -> 11000 | K34: =SUMIF('31'!$M$3:$M$13,"MUTOK35",'31'!$K$3:$K$13) -> 0 | L34: =SUMIF('31'!$M$3:$M$13,"MUTOK35",'31'!$L$3:$L$13) -> 0 | M34: =(M33)+(K34-L34) -> 5000 | N34: =SUM(B34+E34+H34+K34) -> 0 | O34: =SUM(C34+F34+I34+L34) -> 0 | P34: =N34-O34 -> 0 | Q34: =(N34)-('31'!$K$14) -> 0 | R34: =(O34)-('31'!$L$14) -> 0
A35: TOPLAM | B35: =SUM(B3:B34) -> 760000 | C35: =SUM(C3:C34) -> 0 | E35: =SUM(E3:E34) -> 0 | F35: =SUM(F3:F34) -> 0 | H35: =SUM(H3:H34) -> 11000 | I35: =SUM(I3:I34) -> 0 | K35: =SUM(K3:K34) -> 5000 | L35: =SUM(L3:L34) -> 0 | N35: =SUM(N4:N34) -> 44000 | O35: =SUM(O4:O34) -> 0 | P35: =SUM(P4:P34) -> 44000

Sheet 1
A1: 45200 | B1: YATIRIM | C1: ÇEKİM | D1: KOMİSYON | E1: KALAN TUTAR | G1: SİTE ÜYELERİ YATIRIM | I1: =B25 -> 23443.87 | K1: KREDİLER
A2: MAKSİ PAYFİX | B2: 13769.87 | C2: 11996 | D2: =((B2*8)/100)+((C2*1)/100) -> 1221.5496 | E2: =(B2-C2)-D2 -> 552.3204 | G2: SİTE ÜYELERİ ÇEKİM | I2: =C25 -> 12496 | K2: EKLENEN | L2: ÖDENEN | M2: ÜYE İSMİ | N2: BAKİYE | O2: HANGİ KASA
A3: MAKSİ PAPARA | B3: 3120 | D3: =((B3*8)/100)+((C3*0)/100) -> 249.6 | E3: =(B3-C3)-D3 -> 2870.4 | G3: TOPLAM ÖDENEN KOMİSYON | I3: =D25 -> 2047.4296 | K3: 40000 | M3: OKİCEY | N3: =K3-L3 -> 40000 | O3: TONY KASA | U3: ÖDEMELER KASASI | Z3: KASALAR ARASI TRANSFER KASASI | AE3: KREDİLER KASASI
A4: MAKSİ HAVALE | B4: 500 | C4: 500 | D4: =((B4*9)/100)+((C4*1)/100) -> 50 | E4: =(B4-C4)-D4 -> -50 | G4: SİTE ÜYELERİ GÜNLÜK KALAN | I4: =E25 -> 8900.4404 | K4: 3000 | M4: MUTOK35 | N4: =K4-L4 -> 3000 | O4: TONY KASA | V4: GİREN | W4: ÇIKAN | X4: KALAN | AA4: GİREN | AB4: ÇIKAN | AC4: KALAN | AF4: GİREN | AG4: ÇIKAN | AH4: KALAN
A5: MAKSİ KRİPTO | D5: =((B5*2)/100)+((C5*3)/100) -> 0 | E5: =(B5-C5)-D5 -> 0 | G5: ÜYELER YATIRIM-ÇEKİM FARKI | I5: =I1-I2 -> 10947.87 | K5: 1000 | M5: KEMALGEZER | N5: =K5-L5 -> 1000 | O5: TONY KASA | U5: MAKSİ KASA | W5: =SUMIF($O$17:$P$24,"MAKSİ KASA",$N$17:$N$24) -> 0 | X5: =V5-W5 -> 0 | Z5: MAKSİ KASA | AA5: =SUMIF($I$19:$I$25,"MAKSİ KASA",$G$19:$G$25) -> 0 | AB5: =SUMIF($I$19:$I$25,"MAKSİ KASA",$H$19:$H$25) -> 0 | AC5: =AA5-AB5 -> 0 | AE5: TONY KASA | AF5: =SUMIF($O$3:$P$13,"TONY KASA",$K$3:$K$13) -> 44000 | AG5: =SUMIF($O$3:$P$13,"TONY KASA",$L$3:$L$13) -> 0 | AH5: =AF5-AG5 -> 44000
A6: MAKSİ PEP | B6: 429 | D6: =((B6*7)/100)+((C6*0)/100) -> 30.03 | E6: =(B6-C6)-D6 -> 398.97 | N6: =K6-L6 -> 0 | U6: PLUS KASA | W6: =SUMIF($O$17:$P$24,"PLUS KASA",$N$17:$N$24) -> 0 | X6: =V6-W6 -> 0 | Z6: PLUS KASA | AA6: =SUMIF($I$19:$I$25,"PLUS KASA",$G$19:$G$25) -> 0 | AB6: =SUMIF($I$19:$I$25,"PLUS KASA",$H$19:$H$25) -> 0 | AC6: =AA6-AB6 -> 0 | AE6: TS KASA | AF6: =SUMIF($O$3:$P$13,"TS KASA",$K$3:$K$13) -> 0 | AG6: =SUMIF($O$3:$P$13,"TS KASA",$L$3:$L$13) -> 0 | AH6: =AF6-AG6 -> 0
A7: MAKSİ PAYBOL&POPYPARA | D7: =((B7*6)/100)+((C7*0)/100) -> 0 | E7: =(B7-C7)-D7 -> 0 | G7: EKLENEN KREDİ TOPLAMI | I7: =K14 -> 44000 | N7: =K7-L7 -> 0 | U7: FTN KASA | W7: =SUMIF($O$17:$P$24,"FTN KASA",$N$17:$N$24) -> 0 | X7: =V7-W7 -> 0 | Z7: FTN KASA | AA7: =SUMIF($I$19:$I$25,"FTN KASA",$G$19:$G$25) -> 0 | AB7: =SUMIF($I$19:$I$25,"FTN KASA",$H$19:$H$25) -> 0 | AC7: =AA7-AB7 -> 0 | AE7: KARTAL KASA | AF7: =SUMIF($O$3:$P$13,"KARTAL KASA",$K$3:$K$13) -> 0 | AG7: =SUMIF($O$3:$P$13,"KARTAL KASA",$L$3:$L$13) -> 0 | AH7: =AF7-AG7 -> 0
A8: MAKSİ OZANPAY | D8: =((B8*6)/100)+((C8*1)/100) -> 0 | E8: =(B8-C8)-D8 -> 0 | G8: ÖDENEN KREDİ TOPLAMI | I8: =L14 -> 0 | N8: =K8-L8 -> 0 | U8: TONY KASA | W8: =SUMIF($O$17:$P$24,"TONY KASA",$N$17:$N$24) -> 0 | X8: =V8-W8 -> 0 | Z8: TONY KASA | AA8: =SUMIF($I$19:$I$25,"TONY KASA",$G$19:$G$25) -> 0 | AB8: =SUMIF($I$19:$I$25,"TONY KASA",$H$19:$H$25) -> 0 | AC8: =AA8-AB8 -> 0 | AE8: ALEX KASA | AF8: =SUMIF($O$3:$P$13,"ALEX KASA",$K$3:$K$13) -> 0 | AG8: =SUMIF($O$3:$P$13,"ALEX KASA",$L$3:$L$13) -> 0 | AH8: =AF8-AG8 -> 0
A9: MAKSİ KREDİ KARTI | D9: =((B9*10)/100) -> 0 | E9: =(B9-C9)-D9 -> 0 | G9: KREDİLER FARK | I9: =I7-I8 -> 44000 | N9: =K9-L9 -> 0 | U9: TS KASA | W9: =SUMIF($O$17:$P$24,"TS KASA",$N$17:$N$24) -> 0 | X9: =V9-W9 -> 0 | Z9: TS KASA | AA9: =SUMIF($I$19:$I$25,"TS KASA",$G$19:$G$25) -> 0 | AB9: =SUMIF($I$19:$I$25,"TS KASA",$H$19:$H$25) -> 0 | AC9: =AA9-AB9 -> 0 | AE9: KORAY KASA | AF9: =SUMIF($O$3:$P$13,"KORAY KASA",$K$3:$K$13) -> 0 | AG9: =SUMIF($O$3:$P$13,"KORAY KASA",$L$3:$L$13) -> 0 | AH9: =AF9-AG9 -> 0
A10: PLUS HAVALE | B10: 4625 | D10: =((B10*9)/100)+((C10*0)/100) -> 416.25 | E10: =(B10-C10)-D10 -> 4208.75 | N10: =K10-L10 -> 0 | U10: KARTAL KASA | W10: =SUMIF($O$17:$P$24,"KARTAL KASA",$N$17:$N$24) -> 0 | X10: =V10-W10 -> 0 | Z10: KARTAL KASA | AA10: =SUMIF($I$19:$I$25,"KARTAL KASA",$G$19:$G$25) -> 0 | AB10: =SUMIF($I$19:$I$25,"KARTAL KASA",$H$19:$H$25) -> 0 | AC10: =AA10-AB10 -> 0 | AH10: =AF10-AG10 -> 0
A11: PLUS PAPARA | B11: 1000 | D11: =((B11*8)/100)+((C11*0)/100) -> 80 | E11: =(B11-C11)-D11 -> 920 | G11: TOPLAM SİTE YATIRIM | I11: =I1+I7 -> 67443.87 | N11: =K11-L11 -> 0 | U11: ALEX KASA | W11: =SUMIF($O$17:$P$24,"ALEX KASA",$N$17:$N$24) -> 0 | X11: =V11-W11 -> 0 | Z11: ALEX KASA | AA11: =SUMIF($I$19:$I$25,"ALEX KASA",$G$19:$G$25) -> 0 | AB11: =SUMIF($I$19:$I$25,"ALEX KASA",$H$19:$H$25) -> 0 | AC11: =AA11-AB11 -> 0 | AH11: =AF11-AG11 -> 0
A12: FTN | D12: =((B12*0)/100)+((C12*0)/100) -> 0 | E12: =(B12-C12)-D12 -> 0 | G12: TOPLAM SİTE ÇEKİM | I12: =I2+I8 -> 12496 | N12: =K12-L12 -> 0 | U12: KORAY KASA | W12: =SUMIF($O$17:$P$24,"KORAY KASA",$N$17:$N$24) -> 0 | X12: =V12-W12 -> 0 | Z12: KORAY KASA | AA12: =SUMIF($I$19:$I$25,"KORAY KASA",$G$19:$G$25) -> 0 | AB12: =SUMIF($I$19:$I$25,"KORAY KASA",$H$19:$H$25) -> 0 | AC12: =AA12-AB12 -> 0 | AH12: =AF12-AG12 -> 0
D13: =((B13*9)/100)+((C13*1)/100) -> 0 | E13: =(B13-C13)-D13 -> 0 | G13: YAPILAN ÖDEMELER | I13: =N25 -> 0 | N13: =K13-L13 -> 0 | T13: TOPLAM | W13: =SUM(W5:W12) -> 0 | X13: =V13-W13 -> 0 | Z13: TOPLAM | AA13: =SUM(AA5:AA12) -> 0 | AB13: =SUM(AB5:AB12) -> 0 | AC13: =AA13-AB13 -> 0 | AE13: TOPLAM | AF13: =SUM(AF5:AF12) -> 44000 | AG13: =SUM(AG5:AG12) -> 0 | AH13: =SUM(AH5:AH12) -> 44000
D14: =((B14*9)/100)+((C14*1)/100) -> 0 | E14: =(B14-C14)-D14 -> 0 | G14: TOPLAM KAR/ZARAR | I14: =I11-(I12+I13+I3) -> 52900.44 | K14: =SUM(K3:K13) -> 44000 | L14: =SUM(L3:L13) -> 0
D15: =((B15*7)/100)+((C15*1)/100) -> 0 | E15: =(B15-C15)-D15 -> 0 | K15: YAPILAN ÖDEMELER
D16: =((B16*9)/100)+((C16*0)/100) -> 0 | E16: =(B16-C16)-D16 -> 0 | K16: ÖDEME YERİ | N16: TUTAR | O16: HANGİ KASA
D17: =((B17*12)/100)+((C17*0)/100) -> 0 | E17: =(B17-C17)-D17 -> 0 | G17: KASALAR ARASI TRANSFER
D18: =((B18*7)/100)+((C20*0)/100) -> 0 | E18: =(B18-C18)-D18 -> 0 | G18: GİREN | H18: ÇIKAN | I18: KASA
D19: =((B19*7)/100)+((C21*0)/100) -> 0 | E19: =(B19-C19)-D19 -> 0
D20: =((B20*7)/100)+((C22*0)/100) -> 0 | E20: =(B20-C20)-D20 -> 0
D21: =((B21*7)/100)+((C23*0)/100) -> 0 | E21: =(B21-C21)-D21 -> 0
D22: =((B22*7)/100)+((C24*0)/100) -> 0 | E22: =(B22-C22)-D22 -> 0
D23: =((B23*7)/100)+((C25*0)/100) -> 0 | E23: =(B23-C23)-D23 -> 0
D24: =((B24*7)/100)+((C26*0)/100) -> 0 | E24: =(B24-C24)-D24 -> 0
A25: NAKİT GİRİŞ TOPLAMI | B25: =SUM(B2:B24) -> 23443.87 | C25: =SUM(C2:C24) -> 12496 | D25: =SUM(D2:D24) -> 2047.4296 | E25: =SUM(E2:E24) -> 8900.4404 | K25: TOPLAM | N25: =SUM(N17:N24) -> 0

Sheet 2
A1: 45201 | B1: YATIRIM | C1: ÇEKİM | D1: KOMİSYON | E1: KALAN TUTAR | G1: SİTE ÜYELERİ YATIRIM | I1: =B25 -> 0 | K1: KREDİLER
A2: MAKSİ PAYFİX | D2: =((B2*8)/100)+((C2*1)/100) -> 0 | E2: =(B2-C2)-D2 -> 0 | G2: SİTE ÜYELERİ ÇEKİM | I2: =C25 -> 0 | K2: EKLENEN | L2: ÖDENEN | M2: ÜYE İSMİ | N2: BAKİYE | O2: HANGİ KASA
A3: MAKSİ PAPARA | D3: =((B3*8)/100)+((C3*0)/100) -> 0 | E3: =(B3-C3)-D3 -> 0 | G3: TOPLAM ÖDENEN KOMİSYON | I3: =D25 -> 0 | N3: =K3-L3 -> 0 | U3: ÖDEMELER KASASI | Z3: KASALAR ARASI TRANSFER KASASI | AE3: KREDİLER KASASI
A4: MAKSİ HAVALE | D4: =((B4*9)/100)+((C4*1)/100) -> 0 | E4: =(B4-C4)-D4 -> 0 | G4: SİTE ÜYELERİ GÜNLÜK KALAN | I4: =E25 -> 0 | N4: =K4-L4 -> 0 | V4: GİREN | W4: ÇIKAN | X4: KALAN | AA4: GİREN | AB4: ÇIKAN | AC4: KALAN | AF4: GİREN | AG4: ÇIKAN | AH4: KALAN
A5: MAKSİ KRİPTO | D5: =((B5*2)/100)+((C5*3)/100) -> 0 | E5: =(B5-C5)-D5 -> 0 | G5: ÜYELER YATIRIM-ÇEKİM FARKI | I5: =I1-I2 -> 0 | N5: =K5-L5 -> 0 | U5: MAKSİ KASA | W5: =SUMIF($O$17:$P$24,"MAKSİ KASA",$N$17:$N$24) -> 0 | X5: =V5-W5 -> 0 | Z5: MAKSİ KASA | AA5: =SUMIF($I$19:$I$25,"MAKSİ KASA",$G$19:$G$25) -> 0 | AB5: =SUMIF($I$19:$I$25,"MAKSİ KASA",$H$19:$H$25) -> 0 | AC5: =AA5-AB5 -> 0 | AE5: TONY KASA | AF5: =SUMIF($O$3:$P$13,"TONY KASA",$K$3:$K$13) -> 0 | AG5: =SUMIF($O$3:$P$13,"TONY KASA",$L$3:$L$13) -> 0 | AH5: =AF5-AG5 -> 0
A6: MAKSİ PEP | D6: =((B6*7)/100)+((C6*0)/100) -> 0 | E6: =(B6-C6)-D6 -> 0 | N6: =K6-L6 -> 0 | U6: PLUS KASA | W6: =SUMIF($O$17:$P$24,"PLUS KASA",$N$17:$N$24) -> 0 | X6: =V6-W6 -> 0 | Z6: PLUS KASA | AA6: =SUMIF($I$19:$I$25,"PLUS KASA",$G$19:$G$25) -> 0 | AB6: =SUMIF($I$19:$I$25,"PLUS KASA",$H$19:$H$25) -> 0 | AC6: =AA6-AB6 -> 0 | AE6: TS KASA | AF6: =SUMIF($O$3:$P$13,"TS KASA",$K$3:$K$13) -> 0 | AG6: =SUMIF($O$3:$P$13,"TS KASA",$L$3:$L$13) -> 0 | AH6: =AF6-AG6 -> 0
A7: MAKSİ PAYBOL&POPYPARA | D7: =((B7*6)/100)+((C7*0)/100) -> 0 | E7: =(B7-C7)-D7 -> 0 | G7: EKLENEN KREDİ TOPLAMI | I7: =K14 -> 0 | N7: =K7-L7 -> 0 | U7: FTN KASA | W7: =SUMIF($O$17:$P$24,"FTN KASA",$N$17:$N$24) -> 0 | X7: =V7-W7 -> 0 | Z7: FTN KASA | AA7: =SUMIF($I$19:$I$25,"FTN KASA",$G$19:$G$25) -> 0 | AB7: =SUMIF($I$19:$I$25,"FTN KASA",$H$19:$H$25) -> 0 | AC7: =AA7-AB7 -> 0 | AE7: KARTAL KASA | AF7: =SUMIF($O$3:$P$13,"KARTAL KASA",$K$3:$K$13) -> 0 | AG7: =SUMIF($O$3:$P$13,"KARTAL KASA",$L$3:$L$13) -> 0 | AH7: =AF7-AG7 -> 0
A8: MAKSİ OZANPAY | D8: =((B8*6)/100)+((C8*1)/100) -> 0 | E8: =(B8-C8)-D8 -> 0 | G8: ÖDENEN KREDİ TOPLAMI | I8: =L14 -> 0 | N8: =K8-L8 -> 0 | U8: TONY KASA | W8: =SUMIF($O$17:$P$24,"TONY KASA",$N$17:$N$24) -> 0 | X8: =V8-W8 -> 0 | Z8: TONY KASA | AA8: =SUMIF($I$19:$I$25,"TONY KASA",$G$19:$G$25) -> 0 | AB8: =SUMIF($I$19:$I$25,"TONY KASA",$H$19:$H$25) -> 0 | AC8: =AA8-AB8 -> 0 | AE8: ALEX KASA | AF8: =SUMIF($O$3:$P$13,"ALEX KASA",$K$3:$K$13) -> 0 | AG8: =SUMIF($O$3:$P$13,"ALEX KASA",$L$3:$L$13) -> 0 | AH8: =AF8-AG8 -> 0
A9: MAKSİ KREDİ KARTI | D9: =((B9*10)/100) -> 0 | E9: =(B9-C9)-D9 -> 0 | G9: KREDİLER FARK | I9: =I7-I8 -> 0 | N9: =K9-L9 -> 0 | U9: TS KASA | W9: =SUMIF($O$17:$P$24,"TS KASA",$N$17:$N$24) -> 0 | X9: =V9-W9 -> 0 | Z9: TS KASA | AA9: =SUMIF($I$19:$I$25,"TS KASA",$G$19:$G$25) -> 0 | AB9: =SUMIF($I$19:$I$25,"TS KASA",$H$19:$H$25) -> 0 | AC9: =AA9-AB9 -> 0 | AE9: KORAY KASA | AF9: =SUMIF($O$3:$P$13,"KORAY KASA",$K$3:$K$13) -> 0 | AG9: =SUMIF($O$3:$P$13,"KORAY KASA",$L$3:$L$13) -> 0 | AH9: =AF9-AG9 -> 0
A10: PLUS HAVALE | D10: =((B10*9)/100)+((C10*0)/100) -> 0 | E10: =(B10-C10)-D10 -> 0 | N10: =K10-L10 -> 0 | U10: KARTAL KASA | W10: =SUMIF($O$17:$P$24,"KARTAL KASA",$N$17:$N$24) -> 0 | X10: =V10-W10 -> 0 | Z10: KARTAL KASA | AA10: =SUMIF($I$19:$I$25,"KARTAL KASA",$G$19:$G$25) -> 0 | AB10: =SUMIF($I$19:$I$25,"KARTAL KASA",$H$19:$H$25) -> 0 | AC10: =AA10-AB10 -> 0 | AH10: =AF10-AG10 -> 0
A11: PLUS PAPARA | D11: =((B11*8)/100)+((C11*0)/100) -> 0 | E11: =(B11-C11)-D11 -> 0 | G11: TOPLAM SİTE YATIRIM | I11: =I1+I7 -> 0 | N11: =K11-L11 -> 0 | U11: ALEX KASA | W11: =SUMIF($O$17:$P$24,"ALEX KASA",$N$17:$N$24) -> 0 | X11: =V11-W11 -> 0 | Z11: ALEX KASA | AA11: =SUMIF($I$19:$I$25,"ALEX KASA",$G$19:$G$25) -> 0 | AB11: =SUMIF($I$19:$I$25,"ALEX KASA",$H$19:$H$25) -> 0 | AC11: =AA11-AB11 -> 0 | AH11: =AF11-AG11 -> 0
A12: FTN | D12: =((B12*0)/100)+((C12*0)/100) -> 0 | E12: =(B12-C12)-D12 -> 0 | G12: TOPLAM SİTE ÇEKİM | I12: =I2+I8 -> 0 | N12: =K12-L12 -> 0 | U12: KORAY KASA | W12: =SUMIF($O$17:$P$24,"KORAY KASA",$N$17:$N$24) -> 0 | X12: =V12-W12 -> 0 | Z12: KORAY KASA | AA12: =SUMIF($I$19:$I$25,"KORAY KASA",$G$19:$G$25) -> 0 | AB12: =SUMIF($I$19:$I$25,"KORAY KASA",$H$19:$H$25) -> 0 | AC12: =AA12-AB12 -> 0 | AH12: =AF12-AG12 -> 0
D13: =((B13*9)/100)+((C13*1)/100) -> 0 | E13: =(B13-C13)-D13 -> 0 | G13: YAPILAN ÖDEMELER | I13: =N25 -> 0 | N13: =K13-L13 -> 0 | T13: TOPLAM | W13: =SUM(W5:W12) -> 0 | X13: =V13-W13 -> 0 | Z13: TOPLAM | AA13: =SUM(AA5:AA12) -> 0 | AB13: =SUM(AB5:AB12) -> 0 | AC13: =AA13-AB13 -> 0 | AE13: TOPLAM | AF13: =SUM(AF5:AF12) -> 0 | AG13: =SUM(AG5:AG12) -> 0 | AH13: =SUM(AH5:AH12) -> 0
D14: =((B14*9)/100)+((C14*1)/100) -> 0 | E14: =(B14-C14)-D14 -> 0 | G14: TOPLAM KAR/ZARAR | I14: =I11-(I12+I13+I3) -> 0 | K14: =SUM(K3:K13) -> 0 | L14: =SUM(L3:L13) -> 0
D15: =((B15*7)/100)+((C15*1)/100) -> 0 | E15: =(B15-C15)-D15 -> 0 | K15: YAPILAN ÖDEMELER
D16: =((B16*9)/100)+((C16*0)/100) -> 0 | E16: =(B16-C16)-D16 -> 0 | K16: ÖDEME YERİ | N16: TUTAR | O16: HANGİ KASA
D17: =((B17*12)/100)+((C17*0)/100) -> 0 | E17: =(B17-C17)-D17 -> 0 | G17: KASALAR ARASI TRANSFER
D18: =((B18*7)/100)+((C20*0)/100) -> 0 | E18: =(B18-C18)-D18 -> 0 | G18: GİREN | H18: ÇIKAN | I18: KASA
D19: =((B19*7)/100)+((C21*0)/100) -> 0 | E19: =(B19-C19)-D19 -> 0
D20: =((B20*7)/100)+((C22*0)/100) -> 0 | E20: =(B20-C20)-D20 -> 0
D21: =((B21*7)/100)+((C23*0)/100) -> 0 | E21: =(B21-C21)-D21 -> 0
D22: =((B22*7)/100)+((C24*0)/100) -> 0 | E22: =(B22-C22)-D22 -> 0
D23: =((B23*7)/100)+((C25*0)/100) -> 0 | E23: =(B23-C23)-D23 -> 0
D24: =((B24*7)/100)+((C26*0)/100) -> 0 | E24: =(B24-C24)-D24 -> 0
A25: NAKİT GİRİŞ TOPLAMI | B25: =SUM(B2:B24) -> 0 | C25: =SUM(C2:C24) -> 0 | D25: =SUM(D2:D24) -> 0 | E25: =SUM(E2:E24) -> 0 | K25: TOPLAM | N25: =SUM(N17:N24) -> 0

Sheet 3
A1: 45202 | B1: YATIRIM | C1: ÇEKİM | D1: KOMİSYON | E1: KALAN TUTAR | G1: SİTE ÜYELERİ YATIRIM | I1: =B25 -> 0 | K1: KREDİLER
A2: MAKSİ PAYFİX | D2: =((B2*8)/100)+((C2*1)/100) -> 0 | E2: =(B2-C2)-D2 -> 0 | G2: SİTE ÜYELERİ ÇEKİM | I2: =C25 -> 0 | K2: EKLENEN | L2: ÖDENEN | M2: ÜYE İSMİ | N2: BAKİYE | O2: HANGİ KASA
A3: MAKSİ PAPARA | D3: =((B3*8)/100)+((C3*0)/100) -> 0 | E3: =(B3-C3)-D3 -> 0 | G3: TOPLAM ÖDENEN KOMİSYON | I3: =D25 -> 0 | N3: =K3-L3 -> 0 | U3: ÖDEMELER KASASI | Z3: KASALAR ARASI TRANSFER KASASI | AE3: KREDİLER KASASI
A4: MAKSİ HAVALE | D4: =((B4*9)/100)+((C4*1)/100) -> 0 | E4: =(B4-C4)-D4 -> 0 | G4: SİTE ÜYELERİ GÜNLÜK KALAN | I4: =E25 -> 0 | N4: =K4-L4 -> 0 | V4: GİREN | W4: ÇIKAN | X4: KALAN | AA4: GİREN | AB4: ÇIKAN | AC4: KALAN | AF4: GİREN | AG4: ÇIKAN | AH4: KALAN
A5: MAKSİ KRİPTO | D5: =((B5*2)/100)+((C5*3)/100) -> 0 | E5: =(B5-C5)-D5 -> 0 | G5: ÜYELER YATIRIM-ÇEKİM FARKI | I5: =I1-I2 -> 0 | N5: =K5-L5 -> 0 | U5: MAKSİ KASA | W5: =SUMIF($O$17:$P$24,"MAKSİ KASA",$N$17:$N$24) -> 0 | X5: =V5-W5 -> 0 | Z5: MAKSİ KASA | AA5: =SUMIF($I$19:$I$25,"MAKSİ KASA",$G$19:$G$25) -> 0 | AB5: =SUMIF($I$19:$I$25,"MAKSİ KASA",$H$19:$H$25) -> 0 | AC5: =AA5-AB5 -> 0 | AE5: TONY KASA | AF5: =SUMIF($O$3:$P$13,"TONY KASA",$K$3:$K$13) -> 0 | AG5: =SUMIF($O$3:$P$13,"TONY KASA",$L$3:$L$13) -> 0 | AH5: =AF5-AG5 -> 0
A6: MAKSİ PEP | D6: =((B6*7)/100)+((C6*0)/100) -> 0 | E6: =(B6-C6)-D6 -> 0 | N6: =K6-L6 -> 0 | U6: PLUS KASA | W6: =SUMIF($O$17:$P$24,"PLUS KASA",$N$17:$N$24) -> 0 | X6: =V6-W6 -> 0 | Z6: PLUS KASA | AA6: =SUMIF($I$19:$I$25,"PLUS KASA",$G$19:$G$25) -> 0 | AB6: =SUMIF($I$19:$I$25,"PLUS KASA",$H$19:$H$25) -> 0 | AC6: =AA6-AB6 -> 0 | AE6: TS KASA | AF6: =SUMIF($O$3:$P$13,"TS KASA",$K$3:$K$13) -> 0 | AG6: =SUMIF($O$3:$P$13,"TS KASA",$L$3:$L$13) -> 0 | AH6: =AF6-AG6 -> 0
A7: MAKSİ PAYBOL&POPYPARA | D7: =((B7*6)/100)+((C7*0)/100) -> 0 | E7: =(B7-C7)-D7 -> 0 | G7: EKLENEN KREDİ TOPLAMI | I7: =K14 -> 0 | N7: =K7-L7 -> 0 | U7: FTN KASA | W7: =SUMIF($O$17:$P$24,"FTN KASA",$N$17:$N$24) -> 0 | X7: =V7-W7 -> 0 | Z7: FTN KASA | AA7: =SUMIF($I$19:$I$25,"FTN KASA",$G$19:$G$25) -> 0 | AB7: =SUMIF($I$19:$I$25,"FTN KASA",$H$19:$H$25) -> 0 | AC7: =AA7-AB7 -> 0 | AE7: KARTAL KASA | AF7: =SUMIF($O$3:$P$13,"KARTAL KASA",$K$3:$K$13) -> 0 | AG7: =SUMIF($O$3:$P$13,"KARTAL KASA",$L$3:$L$13) -> 0 | AH7: =AF7-AG7 -> 0
A8: MAKSİ OZANPAY | D8: =((B8*6)/100)+((C8*1)/100) -> 0 | E8: =(B8-C8)-D8 -> 0 | G8: ÖDENEN KREDİ TOPLAMI | I8: =L14 -> 0 | N8: =K8-L8 -> 0 | U8: TONY KASA | W8: =SUMIF($O$17:$P$24,"TONY KASA",$N$17:$N$24) -> 0 | X8: =V8-W8 -> 0 | Z8: TONY KASA | AA8: =SUMIF($I$19:$I$25,"TONY KASA",$G$19:$G$25) -> 0 | AB8: =SUMIF($I$19:$I$25,"TONY KASA",$H$19:$H$25) -> 0 | AC8: =AA8-AB8 -> 0 | AE8: ALEX KASA | AF8: =SUMIF($O$3:$P$13,"ALEX KASA",$K$3:$K$13) -> 0 | AG8: =SUMIF($O$3:$P$13,"ALEX KASA",$L$3:$L$13) -> 0 | AH8: =AF8-AG8 -> 0
A9: MAKSİ KREDİ KARTI | D9: =((B9*10)/100) -> 0 | E9: =(B9-C9)-D9 -> 0 | G9: KREDİLER FARK | I9: =I7-I8 -> 0 | N9: =K9-L9 -> 0 | U9: TS KASA | W9: =SUMIF($O$17:$P$24,"TS KASA",$N$17:$N$24) -> 0 | X9: =V9-W9 -> 0 | Z9: TS KASA | AA9: =SUMIF($I$19:$I$25,"TS KASA",$G$19:$G$25) -> 0 | AB9: =SUMIF($I$19:$I$25,"TS KASA",$H$19:$H$25) -> 0 | AC9: =AA9-AB9 -> 0 | AE9: KORAY KASA | AF9: =SUMIF($O$3:$P$13,"KORAY KASA",$K$3:$K$13) -> 0 | AG9: =SUMIF($O$3:$P$13,"KORAY KASA",$L$3:$L$13) -> 0 | AH9: =AF9-AG9 -> 0
A10: PLUS HAVALE | D10: =((B10*9)/100)+((C10*0)/100) -> 0 | E10: =(B10-C10)-D10 -> 0 | N10: =K10-L10 -> 0 | U10: KARTAL KASA | W10: =SUMIF($O$17:$P$24,"KARTAL KASA",$N$17:$N$24) -> 0 | X10: =V10-W10 -> 0 | Z10: KARTAL KASA | AA10: =SUMIF($I$19:$I$25,"KARTAL KASA",$G$19:$G$25) -> 0 | AB10: =SUMIF($I$19:$I$25,"KARTAL KASA",$H$19:$H$25) -> 0 | AC10: =AA10-AB10 -> 0 | AH10: =AF10-AG10 -> 0
A11: PLUS PAPARA | D11: =((B11*8)/100)+((C11*0)/100) -> 0 | E11: =(B11-C11)-D11 -> 0 | G11: TOPLAM SİTE YATIRIM | I11: =I1+I7 -> 0 | N11: =K11-L11 -> 0 | U11: ALEX KASA | W11: =SUMIF($O$17:$P$24,"ALEX KASA",$N$17:$N$24) -> 0 | X11: =V11-W11 -> 0 | Z11: ALEX KASA | AA11: =SUMIF($I$19:$I$25,"ALEX KASA",$G$19:$G$25) -> 0 | AB11: =SUMIF($I$19:$I$25,"ALEX KASA",$H$19:$H$25) -> 0 | AC11: =AA11-AB11 -> 0 | AH11: =AF11-AG11 -> 0
A12: FTN | D12: =((B12*0)/100)+((C12*0)/100) -> 0 | E12: =(B12-C12)-D12 -> 0 | G12: TOPLAM SİTE ÇEKİM | I12: =I2+I8 -> 0 | N12: =K12-L12 -> 0 | U12: KORAY KASA | W12: =SUMIF($O$17:$P$24,"KORAY KASA",$N$17:$N$24) -> 0 | X12: =V12-W12 -> 0 | Z12: KORAY KASA | AA12: =SUMIF($I$19:$I$25,"KORAY KASA",$G$19:$G$25) -> 0 | AB12: =SUMIF($I$19:$I$25,"KORAY KASA",$H$19:$H$25) -> 0 | AC12: =AA12-AB12 -> 0 | AH12: =AF12-AG12 -> 0
D13: =((B13*9)/100)+((C13*1)/100) -> 0 | E13: =(B13-C13)-D13 -> 0 | G13: YAPILAN ÖDEMELER | I13: =N25 -> 0 | N13: =K13-L13 -> 0 | T13: TOPLAM | W13: =SUM(W5:W12) -> 0 | X13: =V13-W13 -> 0 | Z13: TOPLAM | AA13: =SUM(AA5:AA12) -> 0 | AB13: =SUM(AB5:AB12) -> 0 | AC13: =AA13-AB13 -> 0 | AE13: TOPLAM | AF13: =SUM(AF5:AF12) -> 0 | AG13: =SUM(AG5:AG12) -> 0 | AH13: =SUM(AH5:AH12) -> 0
D14: =((B14*9)/100)+((C14*1)/100) -> 0 | E14: =(B14-C14)-D14 -> 0 | G14: TOPLAM KAR/ZARAR | I14: =I11-(I12+I13+I3) -> 0 | K14: =SUM(K3:K13) -> 0 | L14: =SUM(L3:L13) -> 0
D15: =((B15*7)/100)+((C15*1)/100) -> 0 | E15: =(B15-C15)-D15 -> 0 | K15: YAPILAN ÖDEMELER
D16: =((B16*9)/100)+((C16*0)/100) -> 0 | E16: =(B16-C16)-D16 -> 0 | K16: ÖDEME YERİ | N16: TUTAR | O16: HANGİ KASA
D17: =((B17*12)/100)+((C17*0)/100) -> 0 | E17: =(B17-C17)-D17 -> 0 | G17: KASALAR ARASI TRANSFER
D18: =((B18*7)/100)+((C20*0)/100) -> 0 | E18: =(B18-C18)-D18 -> 0 | G18: GİREN | H18: ÇIKAN | I18: KASA
D19: =((B19*7)/100)+((C21*0)/100) -> 0 | E19: =(B19-C19)-D19 -> 0
D20: =((B20*7)/100)+((C22*0)/100) -> 0 | E20: =(B20-C20)-D20 -> 0
D21: =((B21*7)/100)+((C23*0)/100) -> 0 | E21: =(B21-C21)-D21 -> 0
D22: =((B22*7)/100)+((C24*0)/100) -> 0 | E22: =(B22-C22)-D22 -> 0
D23: =((B23*7)/100)+((C25*0)/100) -> 0 | E23: =(B23-C23)-D23 -> 0
D24: =((B24*7)/100)+((C26*0)/100) -> 0 | E24: =(B24-C24)-D24 -> 0
A25: NAKİT GİRİŞ TOPLAMI | B25: =SUM(B2:B24) -> 0 | C25: =SUM(C2:C24) -> 0 | D25: =SUM(D2:D24) -> 0 | E25: =SUM(E2:E24) -> 0 | K25: TOPLAM | N25: =SUM(N17:N24) -> 0

Sheet 4
A1: 45203 | B1: YATIRIM | C1: ÇEKİM | D1: KOMİSYON | E1: KALAN TUTAR | G1: SİTE ÜYELERİ YATIRIM | I1: =B25 -> 0 | K1: KREDİLER
A2: MAKSİ PAYFİX | D2: =((B2*8)/100)+((C2*1)/100) -> 0 | E2: =(B2-C2)-D2 -> 0 | G2: SİTE ÜYELERİ ÇEKİM | I2: =C25 -> 0 | K2: EKLENEN | L2: ÖDENEN | M2: ÜYE İSMİ | N2: BAKİYE | O2: HANGİ KASA
A3: MAKSİ PAPARA | D3: =((B3*8)/100)+((C3*0)/100) -> 0 | E3: =(B3-C3)-D3 -> 0 | G3: TOPLAM ÖDENEN KOMİSYON | I3: =D25 -> 0 | N3: =K3-L3 -> 0 | U3: ÖDEMELER KASASI | Z3: KASALAR ARASI TRANSFER KASASI | AE3: KREDİLER KASASI
A4: MAKSİ HAVALE | D4: =((B4*9)/100)+((C4*1)/100) -> 0 | E4: =(B4-C4)-D4 -> 0 | G4: SİTE ÜYELERİ GÜNLÜK KALAN | I4: =E25 -> 0 | N4: =K4-L4 -> 0 | V4: GİREN | W4: ÇIKAN | X4: KALAN | AA4: GİREN | AB4: ÇIKAN | AC4: KALAN | AF4: GİREN | AG4: ÇIKAN | AH4: KALAN
A5: MAKSİ KRİPTO | D5: =((B5*2)/100)+((C5*3)/100) -> 0 | E5: =(B5-C5)-D5 -> 0 | G5: ÜYELER YATIRIM-ÇEKİM FARKI | I5: =I1-I2 -> 0 | N5: =K5-L5 -> 0 | U5: MAKSİ KASA | W5: =SUMIF($O$17:$P$24,"MAKSİ KASA",$N$17:$N$24) -> 0 | X5: =V5-W5 -> 0 | Z5: MAKSİ KASA | AA5: =SUMIF($I$19:$I$25,"MAKSİ KASA",$G$19:$G$25) -> 0 | AB5: =SUMIF($I$19:$I$25,"MAKSİ KASA",$H$19:$H$25) -> 0 | AC5: =AA5-AB5 -> 0 | AE5: TONY KASA | AF5: =SUMIF($O$3:$P$13,"TONY KASA",$K$3:$K$13) -> 0 | AG5: =SUMIF($O$3:$P$13,"TONY KASA",$L$3:$L$13) -> 0 | AH5: =AF5-AG5 -> 0
A6: MAKSİ PEP | D6: =((B6*7)/100)+((C6*0)/100) -> 0 | E6: =(B6-C6)-D6 -> 0 | N6: =K6-L6 -> 0 | U6: PLUS KASA | W6: =SUMIF($O$17:$P$24,"PLUS KASA",$N$17:$N$24) -> 0 | X6: =V6-W6 -> 0 | Z6: PLUS KASA | AA6: =SUMIF($I$19:$I$25,"PLUS KASA",$G$19:$G$25) -> 0 | AB6: =SUMIF($I$19:$I$25,"PLUS KASA",$H$19:$H$25) -> 0 | AC6: =AA6-AB6 -> 0 | AE6: TS KASA | AF6: =SUMIF($O$3:$P$13,"TS KASA",$K$3:$K$13) -> 0 | AG6: =SUMIF($O$3:$P$13,"TS KASA",$L$3:$L$13) -> 0 | AH6: =AF6-AG6 -> 0
A7: MAKSİ PAYBOL&POPYPARA | D7: =((B7*6)/100)+((C7*0)/100) -> 0 | E7: =(B7-C7)-D7 -> 0 | G7: EKLENEN KREDİ TOPLAMI | I7: =K14 -> 0 | N7: =K7-L7 -> 0 | U7: FTN KASA | W7: =SUMIF($O$17:$P$24,"FTN KASA",$N$17:$N$24) -> 0 | X7: =V7-W7 -> 0 | Z7: FTN KASA | AA7: =SUMIF($I$19:$I$25,"FTN KASA",$G$19:$G$25) -> 0 | AB7: =SUMIF($I$19:$I$25,"FTN KASA",$H$19:$H$25) -> 0 | AC7: =AA7-AB7 -> 0 | AE7: KARTAL KASA | AF7: =SUMIF($O$3:$P$13,"KARTAL KASA",$K$3:$K$13) -> 0 | AG7: =SUMIF($O$3:$P$13,"KARTAL KASA",$L$3:$L$13) -> 0 | AH7: =AF7-AG7 -> 0
A8: MAKSİ OZANPAY | D8: =((B8*6)/100)+((C8*1)/100) -> 0 | E8: =(B8-C8)-D8 -> 0 | G8: ÖDENEN KREDİ TOPLAMI | I8: =L14 -> 0 | N8: =K8-L8 -> 0 | U8: TONY KASA | W8: =SUMIF($O$17:$P$24,"TONY KASA",$N$17:$N$24) -> 0 | X8: =V8-W8 -> 0 | Z8: TONY KASA | AA8: =SUMIF($I$19:$I$25,"TONY KASA",$G$19:$G$25) -> 0 | AB8: =SUMIF($I$19:$I$25,"TONY KASA",$H$19:$H$25) -> 0 | AC8: =AA8-AB8 -> 0 | AE8: ALEX KASA | AF8: =SUMIF($O$3:$P$13,"ALEX KASA",$K$3:$K$13) -> 0 | AG8: =SUMIF($O$3:$P$13,"ALEX KASA",$L$3:$L$13) -> 0 | AH8: =AF8-AG8 -> 0
A9: MAKSİ KREDİ KARTI | D9: =((B9*10)/100) -> 0 | E9: =(B9-C9)-D9 -> 0 | G9: KREDİLER FARK | I9: =I7-I8 -> 0 | N9: =K9-L9 -> 0 | U9: TS KASA | W9: =SUMIF($O$17:$P$24,"TS KASA",$N$17:$N$24) -> 0 | X9: =V9-W9 -> 0 | Z9: TS KASA | AA9: =SUMIF($I$19:$I$25,"TS KASA",$G$19:$G$25) -> 0 | AB9: =SUMIF($I$19:$I$25,"TS KASA",$H$19:$H$25) -> 0 | AC9: =AA9-AB9 -> 0 | AE9: KORAY KASA | AF9: =SUMIF($O$3:$P$13,"KORAY KASA",$K$3:$K$13) -> 0 | AG9: =SUMIF($O$3:$P$13,"KORAY KASA",$L$3:$L$13) -> 0 | AH9: =AF9-AG9 -> 0
A10: PLUS HAVALE | D10: =((B10*9)/100)+((C10*0)/100) -> 0 | E10: =(B10-C10)-D10 -> 0 | N10: =K10-L10 -> 0 | U10: KARTAL KASA | W10: =SUMIF($O$17:$P$24,"KARTAL KASA",$N$17:$N$24) -> 0 | X10: =V10-W10 -> 0 | Z10: KARTAL KASA | AA10: =SUMIF($I$19:$I$25,"KARTAL KASA",$G$19:$G$25) -> 0 | AB10: =SUMIF($I$19:$I$25,"KARTAL KASA",$H$19:$H$25) -> 0 | AC10: =AA10-AB10 -> 0 | AH10: =AF10-AG10 -> 0
A11: PLUS PAPARA | D11: =((B11*8)/100)+((C11*0)/100) -> 0 | E11: =(B11-C11)-D11 -> 0 | G11: TOPLAM SİTE YATIRIM | I11: =I1+I7 -> 0 | N11: =K11-L11 -> 0 | U11: ALEX KASA | W11: =SUMIF($O$17:$P$24,"ALEX KASA",$N$17:$N$24) -> 0 | X11: =V11-W11 -> 0 | Z11: ALEX KASA | AA11: =SUMIF($I$19:$I$25,"ALEX KASA",$G$19:$G$25) -> 0 | AB11: =SUMIF($I$19:$I$25,"ALEX KASA",$H$19:$H$25) -> 0 | AC11: =AA11-AB11 -> 0 | AH11: =AF11-AG11 -> 0
A12: FTN | D12: =((B12*0)/100)+((C12*0)/100) -> 0 | E12: =(B12-C12)-D12 -> 0 | G12: TOPLAM SİTE ÇEKİM | I12: =I2+I8 -> 0 | N12: =K12-L12 -> 0 | U12: KORAY KASA | W12: =SUMIF($O$17:$P$24,"KORAY KASA",$N$17:$N$24) -> 0 | X12: =V12-W12 -> 0 | Z12: KORAY KASA | AA12: =SUMIF($I$19:$I$25,"KORAY KASA",$G$19:$G$25) -> 0 | AB12: =SUMIF($I$19:$I$25,"KORAY KASA",$H$19:$H$25) -> 0 | AC12: =AA12-AB12 -> 0 | AH12: =AF12-AG12 -> 0
D13: =((B13*9)/100)+((C13*1)/100) -> 0 | E13: =(B13-C13)-D13 -> 0 | G13: YAPILAN ÖDEMELER | I13: =N25 -> 0 | N13: =K13-L13 -> 0 | T13: TOPLAM | W13: =SUM(W5:W12) -> 0 | X13: =V13-W13 -> 0 | Z13: TOPLAM | AA13: =SUM(AA5:AA12) -> 0 | AB13: =SUM(AB5:AB12) -> 0 | AC13: =AA13-AB13 -> 0 | AE13: TOPLAM | AF13: =SUM(AF5:AF12) -> 0 | AG13: =SUM(AG5:AG12) -> 0 | AH13: =SUM(AH5:AH12) -> 0
D14: =((B14*9)/100)+((C14*1)/100) -> 0 | E14: =(B14-C14)-D14 -> 0 | G14: TOPLAM KAR/ZARAR | I14: =I11-(I12+I13+I3) -> 0 | K14: =SUM(K3:K13) -> 0 | L14: =SUM(L3:L13) -> 0
D15: =((B15*7)/100)+((C15*1)/100) -> 0 | E15: =(B15-C15)-D15 -> 0 | K15: YAPILAN ÖDEMELER
D16: =((B16*9)/100)+((C16*0)/100) -> 0 | E16: =(B16-C16)-D16 -> 0 | K16: ÖDEME YERİ | N16: TUTAR | O16: HANGİ KASA
D17: =((B17*12)/100)+((C17*0)/100) -> 0 | E17: =(B17-C17)-D17 -> 0 | G17: KASALAR ARASI TRANSFER
D18: =((B18*7)/100)+((C20*0)/100) -> 0 | E18: =(B18-C18)-D18 -> 0 | G18: GİREN | H18: ÇIKAN | I18: KASA
D19: =((B19*7)/100)+((C21*0)/100) -> 0 | E19: =(B19-C19)-D19 -> 0
D20: =((B20*7)/100)+((C22*0)/100) -> 0 | E20: =(B20-C20)-D20 -> 0
D21: =((B21*7)/100)+((C23*0)/100) -> 0 | E21: =(B21-C21)-D21 -> 0
D22: =((B22*7)/100)+((C24*0)/100) -> 0 | E22: =(B22-C22)-D22 -> 0
D23: =((B23*7)/100)+((C25*0)/100) -> 0 | E23: =(B23-C23)-D23 -> 0
D24: =((B24*7)/100)+((C26*0)/100) -> 0 | E24: =(B24-C24)-D24 -> 0
A25: NAKİT GİRİŞ TOPLAMI | B25: =SUM(B2:B24) -> 0 | C25: =SUM(C2:C24) -> 0 | D25: =SUM(D2:D24) -> 0 | E25: =SUM(E2:E24) -> 0 | K25: TOPLAM | N25: =SUM(N17:N24) -> 0

Sheet 5
A1: 45204 | B1: YATIRIM | C1: ÇEKİM | D1: KOMİSYON | E1: KALAN TUTAR | G1: SİTE ÜYELERİ YATIRIM | I1: =B25 -> 0 | K1: KREDİLER
A2: MAKSİ PAYFİX | D2: =((B2*8)/100)+((C2*1)/100) -> 0 | E2: =(B2-C2)-D2 -> 0 | G2: SİTE ÜYELERİ ÇEKİM | I2: =C25 -> 0 | K2: EKLENEN | L2: ÖDENEN | M2: ÜYE İSMİ | N2: BAKİYE | O2: HANGİ KASA
A3: MAKSİ PAPARA | D3: =((B3*8)/100)+((C3*0)/100) -> 0 | E3: =(B3-C3)-D3 -> 0 | G3: TOPLAM ÖDENEN KOMİSYON | I3: =D25 -> 0 | N3: =K3-L3 -> 0 | U3: ÖDEMELER KASASI | Z3: KASALAR ARASI TRANSFER KASASI | AE3: KREDİLER KASASI
A4: MAKSİ HAVALE | D4: =((B4*9)/100)+((C4*1)/100) -> 0 | E4: =(B4-C4)-D4 -> 0 | G4: SİTE ÜYELERİ GÜNLÜK KALAN | I4: =E25 -> 0 | N4: =K4-L4 -> 0 | V4: GİREN | W4: ÇIKAN | X4: KALAN | AA4: GİREN | AB4: ÇIKAN | AC4: KALAN | AF4: GİREN | AG4: ÇIKAN | AH4: KALAN
A5: MAKSİ KRİPTO | D5: =((B5*2)/100)+((C5*3)/100) -> 0 | E5: =(B5-C5)-D5 -> 0 | G5: ÜYELER YATIRIM-ÇEKİM FARKI | I5: =I1-I2 -> 0 | N5: =K5-L5 -> 0 | U5: MAKSİ KASA | W5: =SUMIF($O$17:$P$24,"MAKSİ KASA",$N$17:$N$24) -> 0 | X5: =V5-W5 -> 0 | Z5: MAKSİ KASA | AA5: =SUMIF($I$19:$I$25,"MAKSİ KASA",$G$19:$G$25) -> 0 | AB5: =SUMIF($I$19:$I$25,"MAKSİ KASA",$H$19:$H$25) -> 0 | AC5: =AA5-AB5 -> 0 | AE5: TONY KASA | AF5: =SUMIF($O$3:$P$13,"TONY KASA",$K$3:$K$13) -> 0 | AG5: =SUMIF($O$3:$P$13,"TONY KASA",$L$3:$L$13) -> 0 | AH5: =AF5-AG5 -> 0
A6: MAKSİ PEP | D6: =((B6*7)/100)+((C6*0)/100) -> 0 | E6: =(B6-C6)-D6 -> 0 | N6: =K6-L6 -> 0 | U6: PLUS KASA | W6: =SUMIF($O$17:$P$24,"PLUS KASA",$N$17:$N$24) -> 0 | X6: =V6-W6 -> 0 | Z6: PLUS KASA | AA6: =SUMIF($I$19:$I$25,"PLUS KASA",$G$19:$G$25) -> 0 | AB6: =SUMIF($I$19:$I$25,"PLUS KASA",$H$19:$H$25) -> 0 | AC6: =AA6-AB6 -> 0 | AE6: TS KASA | AF6: =SUMIF($O$3:$P$13,"TS KASA",$K$3:$K$13) -> 0 | AG6: =SUMIF($O$3:$P$13,"TS KASA",$L$3:$L$13) -> 0 | AH6: =AF6-AG6 -> 0
A7: MAKSİ PAYBOL&POPYPARA | D7: =((B7*6)/100)+((C7*0)/100) -> 0 | E7: =(B7-C7)-D7 -> 0 | G7: EKLENEN KREDİ TOPLAMI | I7: =K14 -> 0 | N7: =K7-L7 -> 0 | U7: FTN KASA | W7: =SUMIF($O$17:$P$24,"FTN KASA",$N$17:$N$24) -> 0 | X7: =V7-W7 -> 0 | Z7: FTN KASA | AA7: =SUMIF($I$19:$I$25,"FTN KASA",$G$19:$G$25) -> 0 | AB7: =SUMIF($I$19:$I$25,"FTN KASA",$H$19:$H$25) -> 0 | AC7: =AA7-AB7 -> 0 | AE7: KARTAL KASA | AF7: =SUMIF($O$3:$P$13,"KARTAL KASA",$K$3:$K$13) -> 0 | AG7: =SUMIF($O$3:$P$13,"KARTAL KASA",$L$3:$L$13) -> 0 | AH7: =AF7-AG7 -> 0
A8: MAKSİ OZANPAY | D8: =((B8*6)/100)+((C8*1)/100) -> 0 | E8: =(B8-C8)-D8 -> 0 | G8: ÖDENEN KREDİ TOPLAMI | I8: =L14 -> 0 | N8: =K8-L8 -> 0 | U8: TONY KASA | W8: =SUMIF($O$17:$P$24,"TONY KASA",$N$17:$N$24) -> 0 | X8: =V8-W8 -> 0 | Z8: TONY KASA | AA8: =SUMIF($I$19:$I$25,"TONY KASA",$G$19:$G$25) -> 0 | AB8: =SUMIF($I$19:$I$25,"TONY KASA",$H$19:$H$25) -> 0 | AC8: =AA8-AB8 -> 0 | AE8: ALEX KASA | AF8: =SUMIF($O$3:$P$13,"ALEX KASA",$K$3:$K$13) -> 0 | AG8: =SUMIF($O$3:$P$13,"ALEX KASA",$L$3:$L$13) -> 0 | AH8: =AF8-AG8 -> 0
A9: MAKSİ KREDİ KARTI | D9: =((B9*10)/100) -> 0 | E9: =(B9-C9)-D9 -> 0 | G9: KREDİLER FARK | I9: =I7-I8 -> 0 | N9: =K9-L9 -> 0 | U9: TS KASA | W9: =SUMIF($O$17:$P$24,"TS KASA",$N$17:$N$24) -> 0 | X9: =V9-W9 -> 0 | Z9: TS KASA | AA9: =SUMIF($I$19:$I$25,"TS KASA",$G$19:$G$25) -> 0 | AB9: =SUMIF($I$19:$I$25,"TS KASA",$H$19:$H$25) -> 0 | AC9: =AA9-AB9 -> 0 | AE9: KORAY KASA | AF9: =SUMIF($O$3:$P$13,"KORAY KASA",$K$3:$K$13) -> 0 | AG9: =SUMIF($O$3:$P$13,"KORAY KASA",$L$3:$L$13) -> 0 | AH9: =AF9-AG9 -> 0
A10: PLUS HAVALE | D10: =((B10*9)/100)+((C10*0)/100) -> 0 | E10: =(B10-C10)-D10 -> 0 | N10: =K10-L10 -> 0 | U10: KARTAL KASA | W10: =SUMIF($O$17:$P$24,"KARTAL KASA",$N$17:$N$24) -> 0 | X10: =V10-W10 -> 0 | Z10: KARTAL KASA | AA10: =SUMIF($I$19:$I$25,"KARTAL KASA",$G$19:$G$25) -> 0 | AB10: =SUMIF($I$19:$I$25,"KARTAL KASA",$H$19:$H$25) -> 0 | AC10: =AA10-AB10 -> 0 | AH10: =AF10-AG10 -> 0
A11: PLUS PAPARA | D11: =((B11*8)/100)+((C11*0)/100) -> 0 | E11: =(B11-C11)-D11 -> 0 | G11: TOPLAM SİTE YATIRIM | I11: =I1+I7 -> 0 | N11: =K11-L11 -> 0 | U11: ALEX KASA | W11: =SUMIF($O$17:$P$24,"ALEX KASA",$N$17:$N$24) -> 0 | X11: =V11-W11 -> 0 | Z11: ALEX KASA | AA11: =SUMIF($I$19:$I$25,"ALEX KASA",$G$19:$G$25) -> 0 | AB11: =SUMIF($I$19:$I$25,"ALEX KASA",$H$19:$H$25) -> 0 | AC11: =AA11-AB11 -> 0 | AH11: =AF11-AG11 -> 0
A12: FTN | D12: =((B12*0)/100)+((C12*0)/100) -> 0 | E12: =(B12-C12)-D12 -> 0 | G12: TOPLAM SİTE ÇEKİM | I12: =I2+I8 -> 0 | N12: =K12-L12 -> 0 | U12: KORAY KASA | W12: =SUMIF($O$17:$P$24,"KORAY KASA",$N$17:$N$24) -> 0 | X12: =V12-W12 -> 0 | Z12: KORAY KASA | AA12: =SUMIF($I$19:$I$25,"KORAY KASA",$G$19:$G$25) -> 0 | AB12: =SUMIF($I$19:$I$25,"KORAY KASA",$H$19:$H$25) -> 0 | AC12: =AA12-AB12 -> 0 | AH12: =AF12-AG12 -> 0
D13: =((B13*9)/100)+((C13*1)/100) -> 0 | E13: =(B13-C13)-D13 -> 0 | G13: YAPILAN ÖDEMELER | I13: =N25 -> 0 | N13: =K13-L13 -> 0 | T13: TOPLAM | W13: =SUM(W5:W12) -> 0 | X13: =V13-W13 -> 0 | Z13: TOPLAM | AA13: =SUM(AA5:AA12) -> 0 | AB13: =SUM(AB5:AB12) -> 0 | AC13: =AA13-AB13 -> 0 | AE13: TOPLAM | AF13: =SUM(AF5:AF12) -> 0 | AG13: =SUM(AG5:AG12) -> 0 | AH13: =SUM(AH5:AH12) -> 0
D14: =((B14*9)/100)+((C14*1)/100) -> 0 | E14: =(B14-C14)-D14 -> 0 | G14: TOPLAM KAR/ZARAR | I14: =I11-(I12+I13+I3) -> 0 | K14: =SUM(K3:K13) -> 0 | L14: =SUM(L3:L13) -> 0
D15: =((B15*7)/100)+((C15*1)/100) -> 0 | E15: =(B15-C15)-D15 -> 0 | K15: YAPILAN ÖDEMELER
D16: =((B16*9)/100)+((C16*0)/100) -> 0 | E16: =(B16-C16)-D16 -> 0 | K16: ÖDEME YERİ | N16: TUTAR | O16: HANGİ KASA
D17: =((B17*12)/100)+((C17*0)/100) -> 0 | E17: =(B17-C17)-D17 -> 0 | G17: KASALAR ARASI TRANSFER
D18: =((B18*7)/100)+((C20*0)/100) -> 0 | E18: =(B18-C18)-D18 -> 0 | G18: GİREN | H18: ÇIKAN | I18: KASA
D19: =((B19*7)/100)+((C21*0)/100) -> 0 | E19: =(B19-C19)-D19 -> 0
D20: =((B20*7)/100)+((C22*0)/100) -> 0 | E20: =(B20-C20)-D20 -> 0
D21: =((B21*7)/100)+((C23*0)/100) -> 0 | E21: =(B21-C21)-D21 -> 0
D22: =((B22*7)/100)+((C24*0)/100) -> 0 | E22: =(B22-C22)-D22 -> 0
